Workbook

Sheet MASTER
A1: ARTICULO | B1: UPC | C1: DESCRIPCIÓN | D1: PROVEEDOR | E1: FAMILIA | F1: SEGMENTO | G1: SABOR | H1: SUBCATEGORIA | I1: ESTATUS | J1: INNOVACION | K1: Contenido | L1: Nivel Nic | M1: Costo | N1: Precio
A2: 100024998 | B2: 7311250046988 | C2: ZYN SPEARMINT 6MG STRONG CAJETILLA PZ | D2: PMI | E2: ZYN | F2: ORAL | G2: F&S | H2: NICOTINE POUCHES | I2: Activo | J2: =+_xlfn.XLOOKUP(B2,INNOVACIÓN!A:A,INNOVACIÓN!B:B,"NO") -> NO | K2: 15 | L2: Medio | M2: =+_xlfn.XLOOKUP(A2,'COSTO Y PRECIO'!$A:$A,'COSTO Y PRECIO'!B:B) -> 47.15 | N2: =+_xlfn.XLOOKUP(A2,'COSTO Y PRECIO'!$A:$A,'COSTO Y PRECIO'!C:C) -> 85
A3: 100024997 | B3: 7311250046971 | C3: ZYN SPEARMINT 3MG MEDIUM CAJETILLA PZ | D3: PMI | E3: ZYN | F3: ORAL | G3: F&S | H3: NICOTINE POUCHES | I3: Activo | J3: =+_xlfn.XLOOKUP(B3,INNOVACIÓN!A:A,INNOVACIÓN!B:B,"NO") -> NO | K3: 15 | L3: Bajo | M3: =+_xlfn.XLOOKUP(A3,'COSTO Y PRECIO'!$A:$A,'COSTO Y PRECIO'!B:B) -> 47.15 | N3: =+_xlfn.XLOOKUP(A3,'COSTO Y PRECIO'!$A:$A,'COSTO Y PRECIO'!C:C) -> 85
A4: 100025304 | B4: 7311250048388 | C4: ZYN SPEARMINIT 1.5MG LOW CAJETILLA PZ | D4: PMI | E4: ZYN | F4: ORAL | G4: F&S | H4: NICOTINE POUCHES | I4: Activo | J4: =+_xlfn.XLOOKUP(B4,INNOVACIÓN!A:A,INNOVACIÓN!B:B,"NO") -> NO | K4: 15 | L4: Extra bajo | M4: =+_xlfn.XLOOKUP(A4,'COSTO Y PRECIO'!$A:$A,'COSTO Y PRECIO'!B:B) -> 47.15 | N4: =+_xlfn.XLOOKUP(A4,'COSTO Y PRECIO'!$A:$A,'COSTO Y PRECIO'!C:C) -> 85
A5: 100026067 | B5: 7311250035579 | C5: ZYN PEACH 6MG STRONG LATA PZ | D5: PMI | E5: ZYN | F5: ORAL | G5: F&S | H5: NICOTINE POUCHES | I5: Activo | J5: =+_xlfn.XLOOKUP(B5,INNOVACIÓN!A:A,INNOVACIÓN!B:B,"NO") -> NO | K5: 15 | L5: Medio | M5: =+_xlfn.XLOOKUP(A5,'COSTO Y PRECIO'!$A:$A,'COSTO Y PRECIO'!B:B) -> 47.15 | N5: =+_xlfn.XLOOKUP(A5,'COSTO Y PRECIO'!$A:$A,'COSTO Y PRECIO'!C:C) -> 85
A6: 100026065 | B6: 7311250035593 | C6: ZYN PEACH 3MG MEDIUM LATA PZ | D6: PMI | E6: ZYN | F6: ORAL | G6: F&S | H6: NICOTINE POUCHES | I6: Activo | J6: =+_xlfn.XLOOKUP(B6,INNOVACIÓN!A:A,INNOVACIÓN!B:B,"NO") -> NO | K6: 15 | L6: Bajo | M6: =+_xlfn.XLOOKUP(A6,'COSTO Y PRECIO'!$A:$A,'COSTO Y PRECIO'!B:B) -> 47.15 | N6: =+_xlfn.XLOOKUP(A6,'COSTO Y PRECIO'!$A:$A,'COSTO Y PRECIO'!C:C) -> 85
A7: 100024400 | B7: 7311250044441 | C7: ZYN ESPRESSINO MINI STRONG UNIDAD PZ | D7: PMI | E7: BYE | F7: ORAL | G7: F&S | H7: NICOTINE POUCHES | I7: Descontinuado (con stock) | J7: =+_xlfn.XLOOKUP(B7,INNOVACIÓN!A:A,INNOVACIÓN!B:B,"NO") -> NO | K7: 15 | L7: Medio | M7: =+_xlfn.XLOOKUP(A7,'COSTO Y PRECIO'!$A:$A,'COSTO Y PRECIO'!B:B) -> 47.15 | N7: =+_xlfn.XLOOKUP(A7,'COSTO Y PRECIO'!$A:$A,'COSTO Y PRECIO'!C:C) -> 85
A8: 100024295 | B8: 7311250044434 | C8: ZYN ESPRESSINO MINI MEDIUM CAJETILLA PZ | D8: PMI | E8: BYE | F8: ORAL | G8: F&S | H8: NICOTINE POUCHES | I8: Descontinuado (con stock) | J8: =+_xlfn.XLOOKUP(B8,INNOVACIÓN!A:A,INNOVACIÓN!B:B,"NO") -> NO | K8: 15 | L8: Bajo | M8: =+_xlfn.XLOOKUP(A8,'COSTO Y PRECIO'!$A:$A,'COSTO Y PRECIO'!B:B) -> 47.15 | N8: =+_xlfn.XLOOKUP(A8,'COSTO Y PRECIO'!$A:$A,'COSTO Y PRECIO'!C:C) -> 85
A9: 100024399 | B9: 7311250044403 | C9: ZYN COOL MINT MINI STRONG UNIDAD PZ | D9: PMI | E9: ZYN | F9: ORAL | G9: F&S | H9: NICOTINE POUCHES | I9: Activo | J9: =+_xlfn.XLOOKUP(B9,INNOVACIÓN!A:A,INNOVACIÓN!B:B,"NO") -> NO | K9: 15 | L9: Medio | M9: =+_xlfn.XLOOKUP(A9,'COSTO Y PRECIO'!$A:$A,'COSTO Y PRECIO'!B:B) -> 47.15 | N9: =+_xlfn.XLOOKUP(A9,'COSTO Y PRECIO'!$A:$A,'COSTO Y PRECIO'!C:C) -> 85
A10: 100024294 | B10: 7311250044397 | C10: ZYN COOL MINT MINI MEDIUM CAJETILLA PZ | D10: PMI | E10: ZYN | F10: ORAL | G10: F&S | H10: NICOTINE POUCHES | I10: Activo | J10: =+_xlfn.XLOOKUP(B10,INNOVACIÓN!A:A,INNOVACIÓN!B:B,"NO") -> NO | K10: 15 | L10: Bajo | M10: =+_xlfn.XLOOKUP(A10,'COSTO Y PRECIO'!$A:$A,'COSTO Y PRECIO'!B:B) -> 47.15 | N10: =+_xlfn.XLOOKUP(A10,'COSTO Y PRECIO'!$A:$A,'COSTO Y PRECIO'!C:C) -> 85
A11: 100026064 | B11: 7311250035562 | C11: ZYN COOL MINT 1.5MG LOW LATA PZ | D11: PMI | E11: ZYN | F11: ORAL | G11: F&S | H11: NICOTINE POUCHES | I11: Activo | J11: =+_xlfn.XLOOKUP(B11,INNOVACIÓN!A:A,INNOVACIÓN!B:B,"NO") -> NO | K11: 15 | L11: Extra bajo | M11: =+_xlfn.XLOOKUP(A11,'COSTO Y PRECIO'!$A:$A,'COSTO Y PRECIO'!B:B) -> 47.15 | N11: =+_xlfn.XLOOKUP(A11,'COSTO Y PRECIO'!$A:$A,'COSTO Y PRECIO'!C:C) -> 85
A12: 100024398 | B12: 7311250044427 | C12: ZYN CITRUS MINI STRONG UNIDAD PZ | D12: PMI | E12: ZYN | F12: ORAL | G12: F&S | H12: NICOTINE POUCHES | I12: Activo | J12: =+_xlfn.XLOOKUP(B12,INNOVACIÓN!A:A,INNOVACIÓN!B:B,"NO") -> NO | K12: 15 | L12: Medio | M12: =+_xlfn.XLOOKUP(A12,'COSTO Y PRECIO'!$A:$A,'COSTO Y PRECIO'!B:B) -> 47.15 | N12: =+_xlfn.XLOOKUP(A12,'COSTO Y PRECIO'!$A:$A,'COSTO Y PRECIO'!C:C) -> 85
A13: 100024293 | B13: 7311250044410 | C13: ZYN CITRUS MINI MEDIUM CAJETILLA PZ | D13: PMI | E13: ZYN | F13: ORAL | G13: F&S | H13: NICOTINE POUCHES | I13: Activo | J13: =+_xlfn.XLOOKUP(B13,INNOVACIÓN!A:A,INNOVACIÓN!B:B,"NO") -> NO | K13: 15 | L13: Bajo | M13: =+_xlfn.XLOOKUP(A13,'COSTO Y PRECIO'!$A:$A,'COSTO Y PRECIO'!B:B) -> 47.15 | N13: =+_xlfn.XLOOKUP(A13,'COSTO Y PRECIO'!$A:$A,'COSTO Y PRECIO'!C:C) -> 85
... A16: 100026062 | B16: 7311250035555 | C16: ZYN BLACK CHERRY 1.5MG LOW LATA PZ | D16: PMI | E16: ZYN | F16: ORAL | G16: F&S | H16: NICOTINE POUCHES | I16: Activo | J16: =+_xlfn.XLOOKUP(B16,INNOVACIÓN!A:A,INNOVACIÓN!B:B,"NO") -> NO | K16: 15 | L16: Extra bajo | M16: =+_xlfn.XLOOKUP(A16,'COSTO Y PRECIO'!$A:$A,'COSTO Y PRECIO'!B:B) -> 47.15 | N16: =+_xlfn.XLOOKUP(A16,'COSTO Y PRECIO'!$A:$A,'COSTO Y PRECIO'!C:C) -> 85
A17: 100022995 | B17: 7503023959520 | C17: WINSTON WINSTON RED 25S 1 PZ | D17: JTI | E17: WINSTON | F17: Bajo-UL | G17: FULL FLAVOR | H17: CIGARROS | I17: Activo | J17: =+_xlfn.XLOOKUP(B17,INNOVACIÓN!A:A,INNOVACIÓN!B:B,"NO") -> NO | K17: 25 | M17: =+_xlfn.XLOOKUP(A17,'COSTO Y PRECIO'!$A:$A,'COSTO Y PRECIO'!B:B) -> 31.5225 | N17: =+_xlfn.XLOOKUP(A17,'COSTO Y PRECIO'!$A:$A,'COSTO Y PRECIO'!C:C) -> 79
A18: 100022996 | B18: 7503023959513 | C18: WINSTON WINSTON RED 20S 1 PZ | D18: JTI | E18: WINSTON | F18: Bajo-UL | G18: FULL FLAVOR | H18: CIGARROS | I18: Activo | J18: =+_xlfn.XLOOKUP(B18,INNOVACIÓN!A:A,INNOVACIÓN!B:B,"NO") -> NO | K18: 20 | M18: =+_xlfn.XLOOKUP(A18,'COSTO Y PRECIO'!$A:$A,'COSTO Y PRECIO'!B:B) -> 31.204 | N18: =+_xlfn.XLOOKUP(A18,'COSTO Y PRECIO'!$A:$A,'COSTO Y PRECIO'!C:C) -> 70
A19: 100025162 | B19: 7503023959452 | C19: WINSTON WINSTON CLASSIC 25S 25 PZ | D19: JTI | E19: BYE | F19: LOW | G19: FULL FLAVOR | H19: CIGARROS | I19: Descontinuado (con stock) | J19: =+_xlfn.XLOOKUP(B19,INNOVACIÓN!A:A,INNOVACIÓN!B:B,"NO") -> NO | K19: 25 | M19: =+_xlfn.XLOOKUP(A19,'COSTO Y PRECIO'!$A:$A,'COSTO Y PRECIO'!B:B) -> 47.4725 | N19: =+_xlfn.XLOOKUP(A19,'COSTO Y PRECIO'!$A:$A,'COSTO Y PRECIO'!C:C) -> 78
A20: 100080896 | B20: 40331362 | C20: WINSTON CIGARR CLASSIC 14S CAJET | D20: JTI | E20: BYE | F20: LOW | G20: FULL FLAVOR | H20: CIGARROS | I20: Descontinuado (con stock) | J20: =+_xlfn.XLOOKUP(B20,INNOVACIÓN!A:A,INNOVACIÓN!B:B,"NO") -> NO | K20: 14 | M20: =+_xlfn.XLOOKUP(A20,'COSTO Y PRECIO'!$A:$A,'COSTO Y PRECIO'!B:B) -> 38.25 | N20: =+_xlfn.XLOOKUP(A20,'COSTO Y PRECIO'!$A:$A,'COSTO Y PRECIO'!C:C) -> 55
A21: 100080898 | B21: 42138051 | C21: WINSTON CIGARR BLUE 20S CAJET | D21: JTI | E21: WINSTON | F21: LOW | G21: FULL FLAVOR | H21: CIGARROS | I21: Activo | J21: =+_xlfn.XLOOKUP(B21,INNOVACIÓN!A:A,INNOVACIÓN!B:B,"NO") -> NO | K21: 20 | M21: =+_xlfn.XLOOKUP(A21,'COSTO Y PRECIO'!$A:$A,'COSTO Y PRECIO'!B:B) -> 47.149 | N21: =+_xlfn.XLOOKUP(A21,'COSTO Y PRECIO'!$A:$A,'COSTO Y PRECIO'!C:C) -> 87
A22: 100025053 | B22: 75081942 | C22: LUCKIES 20S | D22: BAT | E22: BYE | F22: VFM | G22: F&S | H22: CIGARROS | I22: Descontinuado (con stock) | J22: =+_xlfn.XLOOKUP(B22,INNOVACIÓN!A:A,INNOVACIÓN!B:B,"NO") -> NO | K22: 20 | M22: =+_xlfn.XLOOKUP(A22,'COSTO Y PRECIO'!$A:$A,'COSTO Y PRECIO'!B:B) -> 57.54 | N22: =+_xlfn.XLOOKUP(A22,'COSTO Y PRECIO'!$A:$A,'COSTO Y PRECIO'!C:C) -> 89
A23: 100024321 | B23: 75080679 | C23: LUCKIES 25S | D23: BAT | E23: BYE | F23: LOW | G23: FULL FLAVOR | H23: CIGARROS | I23: Descontinuado (con stock) | J23: =+_xlfn.XLOOKUP(B23,INNOVACIÓN!A:A,INNOVACIÓN!B:B,"NO") -> NO | K23: 25 | M23: =+_xlfn.XLOOKUP(A23,'COSTO Y PRECIO'!$A:$A,'COSTO Y PRECIO'!B:B) -> 64.01 | N23: =+_xlfn.XLOOKUP(A23,'COSTO Y PRECIO'!$A:$A,'COSTO Y PRECIO'!C:C) -> 99
A24: 100012153 | B24: 75063504 | C24: LUCKY STRIKE 20S ME TDC 1PZ | D24: BAT | E24: LUCKY STRIKE | F24: PREMIUM | G24: F&S | H24: CIGARROS | I24: Activo | J24: =+_xlfn.XLOOKUP(B24,INNOVACIÓN!A:A,INNOVACIÓN!B:B,"NO") -> NO | K24: 20 | M24: =+_xlfn.XLOOKUP(A24,'COSTO Y PRECIO'!$A:$A,'COSTO Y PRECIO'!B:B) -> 68.53 | N24: =+_xlfn.XLOOKUP(A24,'COSTO Y PRECIO'!$A:$A,'COSTO Y PRECIO'!C:C) -> 106
A25: 100080955 | B25: 75046521 | C25: LUCKY STRIKE AMARILLOS 20S | D25: BAT | E25: LUCKY STRIKE | F25: VFM | G25: FULL FLAVOR | H25: CIGARROS | I25: Activo | J25: =+_xlfn.XLOOKUP(B25,INNOVACIÓN!A:A,INNOVACIÓN!B:B,"NO") -> NO | K25: 20 | M25: =+_xlfn.XLOOKUP(A25,'COSTO Y PRECIO'!$A:$A,'COSTO Y PRECIO'!B:B) -> 59.48 | N25: =+_xlfn.XLOOKUP(A25,'COSTO Y PRECIO'!$A:$A,'COSTO Y PRECIO'!C:C) -> 92
A26: 100080952 | B26: 75046545 | C26: LUCKY STRIKE AMARILLOS 25S | D26: BAT | E26: LUCKY STRIKE | F26: VFM | G26: FULL FLAVOR | H26: CIGARROS | I26: Activo | J26: =+_xlfn.XLOOKUP(B26,INNOVACIÓN!A:A,INNOVACIÓN!B:B,"NO") -> NO | K26: 25 | M26: =+_xlfn.XLOOKUP(A26,'COSTO Y PRECIO'!$A:$A,'COSTO Y PRECIO'!B:B) -> 64.01 | N26: =+_xlfn.XLOOKUP(A26,'COSTO Y PRECIO'!$A:$A,'COSTO Y PRECIO'!C:C) -> 99
A27: 100004788 | B27: 75051785 | C27: LUCKY STRIKE CLICK 4 MIX | D27: BAT | E27: LUCKY STRIKE | F27: PREMIUM | G27: ME | H27: CIGARROS | I27: Activo | J27: =+_xlfn.XLOOKUP(B27,INNOVACIÓN!A:A,INNOVACIÓN!B:B,"NO") -> NO | K27: 20 | M27: =+_xlfn.XLOOKUP(A27,'COSTO Y PRECIO'!$A:$A,'COSTO Y PRECIO'!B:B) -> 68.53 | N27: =+_xlfn.XLOOKUP(A27,'COSTO Y PRECIO'!$A:$A,'COSTO Y PRECIO'!C:C) -> 106
A28: 100019550 | B28: 75074227 | C28: LUCKY STRIKE COMET 20S 1 CAJETILLA | D28: BAT | E28: LUCKY STRIKE | F28: VFM | G28: MENTHOL | H28: CIGARROS | I28: Activo | J28: =+_xlfn.XLOOKUP(B28,INNOVACIÓN!A:A,INNOVACIÓN!B:B,"NO") -> NO | K28: 20 | M28: =+_xlfn.XLOOKUP(A28,'COSTO Y PRECIO'!$A:$A,'COSTO Y PRECIO'!B:B) -> 63.36 | N28: =+_xlfn.XLOOKUP(A28,'COSTO Y PRECIO'!$A:$A,'COSTO Y PRECIO'!C:C) -> 98
A29: 100012997 | B29: 75064716 | C29: LUCKY STRIKE ENIGMA 100S 1PZ | D29: BAT | E29: LUCKY STRIKE | F29: VFM | G29: F&S | H29: CIGARROS | I29: Activo | J29: =+_xlfn.XLOOKUP(B29,INNOVACIÓN!A:A,INNOVACIÓN!B:B,"NO") -> NO | K29: 20 | M29: =+_xlfn.XLOOKUP(A29,'COSTO Y PRECIO'!$A:$A,'COSTO Y PRECIO'!B:B) -> 63.36 | N29: =+_xlfn.XLOOKUP(A29,'COSTO Y PRECIO'!$A:$A,'COSTO Y PRECIO'!C:C) -> 98
A30: 100026068 | B30: 75084332 | C30: LUCKY STRIKE LUCKIES STICK 20S 20 PZ | D30: BAT | E30: BYE | F30: VFM | H30: CIGARROS | I30: Descontinuado (con stock) | J30: =+_xlfn.XLOOKUP(B30,INNOVACIÓN!A:A,INNOVACIÓN!B:B,"NO") -> NO | K30: 20 | M30: =+_xlfn.XLOOKUP(A30,'COSTO Y PRECIO'!$A:$A,'COSTO Y PRECIO'!B:B) -> 56.25 | N30: =+_xlfn.XLOOKUP(A30,'COSTO Y PRECIO'!$A:$A,'COSTO Y PRECIO'!C:C) -> 87
A31: 100011590 | B31: 7501031700028 | C31: LUCKY STRIKE OR255 PPROMO 1PZ | D31: BAT | E31: BYE | F31: PREMIUM | G31: FF | H31: CIGARROS | I31: Descontinuado (con stock) | J31: =+_xlfn.XLOOKUP(B31,INNOVACIÓN!A:A,INNOVACIÓN!B:B,"NO") -> NO | K31: 25 | M31: =+_xlfn.XLOOKUP(A31,'COSTO Y PRECIO'!$A:$A,'COSTO Y PRECIO'!B:B) -> 50 | N31: =+_xlfn.XLOOKUP(A31,'COSTO Y PRECIO'!$A:$A,'COSTO Y PRECIO'!C:C) -> #N/A
A32: 100080975 | B32: 75048129 | C32: LUCKY STRIKE ORIGINAL FF 20S TUBE | D32: BAT | E32: LUCKY STRIKE | F32: VFM | G32: FULL FLAVOR | H32: CIGARROS | I32: Activo | J32: =+_xlfn.XLOOKUP(B32,INNOVACIÓN!A:A,INNOVACIÓN!B:B,"NO") -> NO | K32: 20 | M32: =+_xlfn.XLOOKUP(A32,'COSTO Y PRECIO'!$A:$A,'COSTO Y PRECIO'!B:B) -> 57.54 | N32: =+_xlfn.XLOOKUP(A32,'COSTO Y PRECIO'!$A:$A,'COSTO Y PRECIO'!C:C) -> 89
A33: 100020970 | B33: 75076405 | C33: MONTANA CLASSI 14S 1 CAJETILLA | D33: BAT | E33: MONTANA | F33: Bajo-UL | G33: FULL FLAVOR | H33: CIGARROS | I33: Activo | J33: =+_xlfn.XLOOKUP(B33,INNOVACIÓN!A:A,INNOVACIÓN!B:B,"NO") -> NO | K33: 14 | M33: =+_xlfn.XLOOKUP(A33,'COSTO Y PRECIO'!$A:$A,'COSTO Y PRECIO'!B:B) -> 33.41 | N33: =+_xlfn.XLOOKUP(A33,'COSTO Y PRECIO'!$A:$A,'COSTO Y PRECIO'!C:C) -> 51
A34: 100020969 | B34: 75076740 | C34: MONTANA CLASSI 20S 1 CAJETILLA | D34: BAT | E34: MONTANA | F34: Bajo-UL | G34: FULL FLAVOR | H34: CIGARROS | I34: Activo | J34: =+_xlfn.XLOOKUP(B34,INNOVACIÓN!A:A,INNOVACIÓN!B:B,"NO") -> NO | K34: 20 | M34: =+_xlfn.XLOOKUP(A34,'COSTO Y PRECIO'!$A:$A,'COSTO Y PRECIO'!B:B) -> 47.17 | N34: =+_xlfn.XLOOKUP(A34,'COSTO Y PRECIO'!$A:$A,'COSTO Y PRECIO'!C:C) -> 72
A35: 100013075 | B35: 75064747 | C35: MONTANA SHOTS 15S 1PZ | D35: BAT | E35: MONTANA | F35: LOW | G35: FULL FLAVOR | H35: CIGARROS | I35: Activo | J35: =+_xlfn.XLOOKUP(B35,INNOVACIÓN!A:A,INNOVACIÓN!B:B,"NO") -> NO | K35: 15 | M35: =+_xlfn.XLOOKUP(A35,'COSTO Y PRECIO'!$A:$A,'COSTO Y PRECIO'!B:B) -> 45.05 | N35: =+_xlfn.XLOOKUP(A35,'COSTO Y PRECIO'!$A:$A,'COSTO Y PRECIO'!C:C) -> 67
A36: 100013892 | B36: 75064754 | C36: MONTANA SHOTS 1PZ | D36: BAT | E36: MONTANA | F36: LOW | G36: FULL FLAVOR | H36: CIGARROS | I36: Activo | J36: =+_xlfn.XLOOKUP(B36,INNOVACIÓN!A:A,INNOVACIÓN!B:B,"NO") -> NO | K36: 20 | M36: =+_xlfn.XLOOKUP(A36,'COSTO Y PRECIO'!$A:$A,'COSTO Y PRECIO'!B:B) -> 66.57 | N36: =+_xlfn.XLOOKUP(A36,'COSTO Y PRECIO'!$A:$A,'COSTO Y PRECIO'!C:C) -> 99
A37: 100023317 | B37: 75078843 | C37: MONTANA SHOTS CLASSICS 25 PZ | D37: BAT | E37: MONTANA | F37: Bajo-UL | G37: FULL FLAVOR | H37: CIGARROS | I37: Activo | J37: =+_xlfn.XLOOKUP(B37,INNOVACIÓN!A:A,INNOVACIÓN!B:B,"NO") -> NO | K37: 25 | M37: =+_xlfn.XLOOKUP(A37,'COSTO Y PRECIO'!$A:$A,'COSTO Y PRECIO'!B:B) -> 53.72 | N37: =+_xlfn.XLOOKUP(A37,'COSTO Y PRECIO'!$A:$A,'COSTO Y PRECIO'!C:C) -> 82
A38: 100016489 | B38: 75071301 | C38: PALL MALL ALASKA DUSK 15 | D38: BAT | E38: BYE | F38: VFM | G38: MENTHOL | H38: CIGARROS | I38: Descontinuado (con stock) | J38: =+_xlfn.XLOOKUP(B38,INNOVACIÓN!A:A,INNOVACIÓN!B:B,"NO") -> NO | K38: 15 | M38: =+_xlfn.XLOOKUP(A38,'COSTO Y PRECIO'!$A:$A,'COSTO Y PRECIO'!B:B) -> 53.79 | N38: =+_xlfn.XLOOKUP(A38,'COSTO Y PRECIO'!$A:$A,'COSTO Y PRECIO'!C:C) -> #N/A
A39: 100016443 | B39: 75071295 | C39: PALL MALL ALASKA DUSK 20 | D39: BAT | E39: PALL MALL | F39: VFM | G39: MENTHOL | H39: CIGARROS | I39: Activo | J39: =+_xlfn.XLOOKUP(B39,INNOVACIÓN!A:A,INNOVACIÓN!B:B,"NO") -> NO | K39: 20 | M39: =+_xlfn.XLOOKUP(A39,'COSTO Y PRECIO'!$A:$A,'COSTO Y PRECIO'!B:B) -> 65.9 | N39: =+_xlfn.XLOOKUP(A39,'COSTO Y PRECIO'!$A:$A,'COSTO Y PRECIO'!C:C) -> 98
A40: 100026387 | B40: 75080501 | C40: PALL MALL ARUBA 20 PZ | D40: BAT | E40: PALL MALL | F40: Medio-Bajo | G40: LOW-TAR | H40: CIGARROS | I40: Activo | J40: =+_xlfn.XLOOKUP(B40,INNOVACIÓN!A:A,INNOVACIÓN!B:B,"NO") -> NO | K40: 20 | M40: =+_xlfn.XLOOKUP(A40,'COSTO Y PRECIO'!$A:$A,'COSTO Y PRECIO'!B:B) -> 51.1 | N40: =+_xlfn.XLOOKUP(A40,'COSTO Y PRECIO'!$A:$A,'COSTO Y PRECIO'!C:C) -> 76
A41: 101000079 | B41: 75079017 | C41: PALL MALL BORA BORA SUNBREAK 20 PZ | D41: BAT | E41: PALL MALL | F41: VFM | G41: F&S | H41: CIGARROS | I41: Activo | J41: =+_xlfn.XLOOKUP(B41,INNOVACIÓN!A:A,INNOVACIÓN!B:B,"NO") -> NO | K41: 20 | M41: =+_xlfn.XLOOKUP(A41,'COSTO Y PRECIO'!$A:$A,'COSTO Y PRECIO'!B:B) -> 65.9 | N41: =+_xlfn.XLOOKUP(A41,'COSTO Y PRECIO'!$A:$A,'COSTO Y PRECIO'!C:C) -> 98
A42: 100025311 | B42: 75083656 | C42: TEREA TWILIGHT PEARL 20 CAJETILLA PZ | D42: PMI | E42: TEREA | F42: LOW | G42: HTP FLAVOUR | H42: HTP | I42: Activo | J42: =+_xlfn.XLOOKUP(B42,INNOVACIÓN!A:A,INNOVACIÓN!B:B,"NO") -> NO | M42: =+_xlfn.XLOOKUP(A42,'COSTO Y PRECIO'!$A:$A,'COSTO Y PRECIO'!B:B) -> 60.12 | N42: =+_xlfn.XLOOKUP(A42,'COSTO Y PRECIO'!$A:$A,'COSTO Y PRECIO'!C:C) -> 85
...

Sheet COSTO Y PRECIO
A1: ARTICULO | B1: COSTO | C1: PRECIO
A2: 100024998 | B2: 47.15 | C2: 85
A3: 100024997 | B3: 47.15 | C3: 85
A4: 100025304 | B4: 47.15 | C4: 85
A5: 100026067 | B5: 47.15 | C5: 85
A6: 100026065 | B6: 47.15 | C6: 85
A7: 100024400 | B7: 47.15 | C7: 85
A8: 100024295 | B8: 47.15 | C8: 85
A9: 100024399 | B9: 47.15 | C9: 85
A10: 100024294 | B10: 47.15 | C10: 85
A11: 100026064 | B11: 47.15 | C11: 85
A12: 100024398 | B12: 47.15 | C12: 85
A13: 100024293 | B13: 47.15 | C13: 85
... A16: 100026062 | B16: 47.15 | C16: 85
A17: 100080917 | B17: 50 | C17: #N/A
A18: 100080184 | B18: 50 | C18: #N/A
A19: 100080865 | B19: 50 | C19: #N/A
A20: 100080895 | B20: 48.195 | C20: #N/A
A21: 100080695 | B21: 50 | C21: #N/A
A22: 100025053 | B22: 57.54 | C22: 89
A23: 100024321 | B23: 64.01 | C23: 99
A24: 100024462 | B24: 61.66 | C24: 80
A25: 100012153 | B25: 68.53 | C25: 106
A26: 100080955 | B26: 59.48 | C26: 92
A27: 100080952 | B27: 64.01 | C27: 99
A28: 100004788 | B28: 68.53 | C28: 106
A29: 100019550 | B29: 63.36 | C29: 98
A30: 100026068 | B30: 56.25 | C30: 87
A31: 100011590 | B31: 50 | C31: #N/A
A32: 100018746 | B32: 45.05 | C32: 67
A33: 100020970 | B33: 33.41 | C33: 51
A34: 100020969 | B34: 47.17 | C34: 72
A35: 100013891 | B35: 66.57 | C35: 99
A36: 100012997 | B36: 63.36 | C36: 98
A37: 100023317 | B37: 53.72 | C37: 82
A38: 100016489 | B38: 53.79 | C38: #N/A
A39: 100013892 | B39: 66.57 | C39: 99
A40: 100026387 | B40: 51.1 | C40: 76
A41: 100016443 | B41: 65.9 | C41: 98
A42: 100025311 | B42: 60.12 | C42: 85
...

Sheet Hoja8

Sheet Hoja4
A1: SKU | B1: UPC | C1: DESCRIPCIÓN | D1: Plazas o Tiendas que Aplica
A2: 100021813 | B2: 7503023959506 | C2: CAMEL MAX DOUBLE 1 27.4 G | D2: Reynosa | E2: SI
A3: 100021813 | B3: 7503023959506 | C3: CAMEL MAX DOUBLE 1 27.4 G | D3: Matamoros | E3: SI
A4: 100021813 | B4: 7503023959506 | C4: CAMEL MAX DOUBLE 1 27.4 G | D4: México | E4: SI
A5: 100021813 | B5: 7503023959506 | C5: CAMEL MAX DOUBLE 1 27.4 G | D5: Jalisco | E5: SI
A6: 100021813 | B6: 7503023959506 | C6: CAMEL MAX DOUBLE 1 27.4 G | D6: Saltillo | E6: SI
A7: 100021813 | B7: 7503023959506 | C7: CAMEL MAX DOUBLE 1 27.4 G | D7: Torreón | E7: SI
A8: 100021813 | B8: 7503023959506 | C8: CAMEL MAX DOUBLE 1 27.4 G | D8: Nuevo León | E8: SI
A9: 100021813 | B9: 7503023959506 | C9: CAMEL MAX DOUBLE 1 27.4 G | D9: Tijuana | E9: SI
A10: 100021813 | B10: 7503023959506 | C10: CAMEL MAX DOUBLE 1 27.4 G | D10: Ensenada | E10: SI
A11: 100021813 | B11: 7503023959506 | C11: CAMEL MAX DOUBLE 1 27.4 G | D11: Mexicali | E11: SI
A12: 100021813 | B12: 7503023959506 | C12: CAMEL MAX DOUBLE 1 27.4 G | D12: Hermosillo | E12: SI
A13: 100021813 | B13: 7503023959506 | C13: CAMEL MAX DOUBLE 1 27.4 G | D13: Puebla | E13: SI
... A301: 75022266 | B301: 100020945 | C301: LM LM 14S 14S 1 CAJETILLA | D301: Quintana Roo | E301: SI
A302: =+_xlfn.XLOOKUP(C302,[1]master!C:C,[1]master!A:A) -> 100019232 | B302: =+_xlfn.XLOOKUP(C302,[1]master!C:C,[1]master!B:B) -> 75074876 | C302: PALL MALL XL RED & CLICK 15S 1 CAJETILLA | D302: México | E302: SI
A303: =+_xlfn.XLOOKUP(C303,[1]master!C:C,[1]master!A:A) -> 100019228 | B303: =+_xlfn.XLOOKUP(C303,[1]master!C:C,[1]master!B:B) -> 75074883 | C303: PALL MALL XL WHITE& CLICK 15S 1 CAJETILLA | D303: México | E303: SI
A304: =+_xlfn.XLOOKUP(C304,[1]master!C:C,[1]master!A:A) -> 100080892 | B304: =+_xlfn.XLOOKUP(C304,[1]master!C:C,[1]master!B:B) -> 75042943 | C304: PALL MALL RED AND CLICK 15 | D304: México | E304: SI
A305: =+_xlfn.XLOOKUP(C305,[1]master!C:C,[1]master!A:A) -> 100080878 | B305: =+_xlfn.XLOOKUP(C305,[1]master!C:C,[1]master!B:B) -> 75039875 | C305: PALL MALL WHITE AND CLICK 15 | D305: México | E305: SI
A306: =+_xlfn.XLOOKUP(C306,[1]master!C:C,[1]master!A:A) -> 100020970 | B306: =+_xlfn.XLOOKUP(C306,[1]master!C:C,[1]master!B:B) -> 75076405 | C306: MONTANA CLASSI 14S 1 CAJETILLA | D306: Morelos | E306: SI
A307: =+_xlfn.XLOOKUP(C307,[1]master!C:C,[1]master!A:A) -> 100020969 | B307: =+_xlfn.XLOOKUP(C307,[1]master!C:C,[1]master!B:B) -> 75076740 | C307: MONTANA CLASSI 20S 1 CAJETILLA | D307: Morelos | E307: SI
A308: =+_xlfn.XLOOKUP(C308,[1]master!C:C,[1]master!A:A) -> 100023317 | B308: =+_xlfn.XLOOKUP(C308,[1]master!C:C,[1]master!B:B) -> 75078843 | C308: MONTANA SHOTS CLASSICS 25 PZ | D308: Morelos | E308: SI
A309: =+_xlfn.XLOOKUP(C309,[1]master!C:C,[1]master!A:A) -> 100019232 | B309: =+_xlfn.XLOOKUP(C309,[1]master!C:C,[1]master!B:B) -> 75074876 | C309: PALL MALL XL RED & CLICK 15S 1 CAJETILLA | D309: Morelos | E309: SI
A310: =+_xlfn.XLOOKUP(C310,[1]master!C:C,[1]master!A:A) -> 100019228 | B310: =+_xlfn.XLOOKUP(C310,[1]master!C:C,[1]master!B:B) -> 75074883 | C310: PALL MALL XL WHITE& CLICK 15S 1 CAJETILLA | D310: Morelos | E310: SI
A311: =+_xlfn.XLOOKUP(C311,[1]master!C:C,[1]master!A:A) -> 100019232 | B311: =+_xlfn.XLOOKUP(C311,[1]master!C:C,[1]master!B:B) -> 75074876 | C311: PALL MALL XL RED & CLICK 15S 1 CAJETILLA | D311: Quintana Roo | E311: SI
A312: =+_xlfn.XLOOKUP(C312,[1]master!C:C,[1]master!A:A) -> 100019228 | B312: =+_xlfn.XLOOKUP(C312,[1]master!C:C,[1]master!B:B) -> 75074883 | C312: PALL MALL XL WHITE& CLICK 15S 1 CAJETILLA | D312: Quintana Roo | E312: SI
A313: =+_xlfn.XLOOKUP(C313,[1]master!C:C,[1]master!A:A) -> 100080892 | B313: =+_xlfn.XLOOKUP(C313,[1]master!C:C,[1]master!B:B) -> 75042943 | C313: PALL MALL RED AND CLICK 15 | D313: Quintana Roo | E313: SI
... A370: =+_xlfn.XLOOKUP(C370,[1]master!C:C,[1]master!A:A) -> 100080878 | B370: =+_xlfn.XLOOKUP(C370,[1]master!C:C,[1]master!B:B) -> 75039875 | C370: PALL MALL WHITE AND CLICK 15 | D370: Yucatán | E370: SI

Sheet INNOVACIÓN
A1: UPC | B1: INNOVACION
A2: 7503023959148 | B2: SI | C2: CAMEL NATURAL FLAVOR 20 | D2: =+_xlfn.XLOOKUP(A2,MASTER!B:B,MASTER!C:C) -> CAMEL NATURAL FLAVOR 20
A3: 7503023959438 | B3: SI | C3: WINSTON OASIS FRES 27.4 G | D3: =+_xlfn.XLOOKUP(A3,MASTER!B:B,MASTER!C:C) -> WINSTON OASIS FRES 27.4 G
A4: 75083762 | B4: SI | C4: PALL MALL PALL MALL SELECT 14 PZ | D4: =+_xlfn.XLOOKUP(A4,MASTER!B:B,MASTER!C:C) -> PALL MALL PALL MALL SELECT 14 PZ
A5: 75083755 | B5: SI | C5: PALL MALL PALL MALL SELECT 20 PZ | D5: =+_xlfn.XLOOKUP(A5,MASTER!B:B,MASTER!C:C) -> PALL MALL PALL MALL SELECT 20 PZ
A6: 75087142 | B6: SI | C6: PALL MALL SUMMER ALASKA 20 PZ | D6: =+_xlfn.XLOOKUP(A6,MASTER!B:B,MASTER!C:C) -> PALL MALL SUMMER ALASKA 20 PZ
A7: 75087159 | B7: SI | C7: PALL MALL SUMMER TOKYO 20 PZ | D7: =+_xlfn.XLOOKUP(A7,MASTER!B:B,MASTER!C:C) -> PALL MALL SUMMER TOKYO 20 PZ
A8: 75087166 | B8: SI | C8: PALL MALL SUMMER MYKONOS 20 PZ | D8: =+_xlfn.XLOOKUP(A8,MASTER!B:B,MASTER!C:C) -> PALL MALL SUMMER MYKONOS 20 PZ
A9: 75087173 | B9: SI | C9: PALL MALL SUMMER HAWAII 20 PZ | D9: =+_xlfn.XLOOKUP(A9,MASTER!B:B,MASTER!C:C) -> PALL MALL SUMMER HAWAII 20 PZ
A10: 75087180 | B10: SI | C10: PALL MALL SUMMER MANILA 20 PZ | D10: =+_xlfn.XLOOKUP(A10,MASTER!B:B,MASTER!C:C) -> PALL MALL SUMMER MANILA 20 PZ
A11: 75087197 | B11: SI | C11: PALL MALL SUMMER SELECT RED 25 PZ | D11: =+_xlfn.XLOOKUP(A11,MASTER!B:B,MASTER!C:C) -> PALL MALL SUMMER SELECT RED 25 PZ
A12: 75087203 | B12: SI | C12: PALL MALL SUMMER SELECT GOLD 14 PZ | D12: =+_xlfn.XLOOKUP(A12,MASTER!B:B,MASTER!C:C) -> PALL MALL SUMMER SELECT GOLD 14 PZ
A13: 75087210 | B13: SI | C13: SHOTS CLASSICS SUMMER 25 PZ | D13: =+_xlfn.XLOOKUP(A13,MASTER!B:B,MASTER!C:C) -> SHOTS CLASSICS SUMMER 25 PZ
... A37: 7502274777464 | B37: SI | C37: SESH CLEAR 10S 2MG 1 PZ | D37: =+_xlfn.XLOOKUP(A37,MASTER!B:B,MASTER!C:C) -> SESH CLEAR 10S 2MG 1 PZ

Sheet Hoja2
A1: articulo | B1: sku | C1: estatus | E1: articulo | F1: sku | G1: estatus
A2: =+_xlfn.XLOOKUP(B2,MASTER!B:B,MASTER!C:C) -> LUCKY STRIKE ORIGINS BRIGHT 20 PZ | B2: 75079895 | C2: =+_xlfn.XLOOKUP(B2,MASTER!B:B,MASTER!I:I) -> Descontinuado (con stock) | E2: =+_xlfn.XLOOKUP(F2,MASTER!B:B,MASTER!C:C) -> LUCKY STRIKE ORIGINS BRIGHT 20 PZ | F2: {=+_xlfn.UNIQUE(B2:B88)} -> 75079895 | G2: =+_xlfn.XLOOKUP(F2,MASTER!B:B,MASTER!I:I) -> Descontinuado (con stock)
A3: =+_xlfn.XLOOKUP(B3,MASTER!B:B,MASTER!C:C) -> LUCKY STRIKE ORIGINS BRIGHT 20 PZ | B3: 75079895 | C3: =+_xlfn.XLOOKUP(B3,MASTER!B:B,MASTER!I:I) -> Descontinuado (con stock) | E3: =+_xlfn.XLOOKUP(F3,MASTER!B:B,MASTER!C:C) -> LUCKY STRIKE ORIGINS DARK 20 PZ | F3: 75079901 | G3: =+_xlfn.XLOOKUP(F3,MASTER!B:B,MASTER!I:I) -> Descontinuado (con stock)
A4: =+_xlfn.XLOOKUP(B4,MASTER!B:B,MASTER!C:C) -> LUCKY STRIKE ORIGINS DARK 20 PZ | B4: 75079901 | C4: =+_xlfn.XLOOKUP(B4,MASTER!B:B,MASTER!I:I) -> Descontinuado (con stock) | E4: =+_xlfn.XLOOKUP(F4,MASTER!B:B,MASTER!C:C) -> LUCKY STRIKE ORIGINS RICH 20 PZ | F4: 75079888 | G4: =+_xlfn.XLOOKUP(F4,MASTER!B:B,MASTER!I:I) -> Descontinuado (con stock)
A5: =+_xlfn.XLOOKUP(B5,MASTER!B:B,MASTER!C:C) -> LUCKY STRIKE ORIGINS DARK 20 PZ | B5: 75079901 | C5: =+_xlfn.XLOOKUP(B5,MASTER!B:B,MASTER!I:I) -> Descontinuado (con stock) | E5: =+_xlfn.XLOOKUP(F5,MASTER!B:B,MASTER!C:C) -> LUCKY STRIKE ORIGINAL RED 20 PZ | F5: 75079956 | G5: =+_xlfn.XLOOKUP(F5,MASTER!B:B,MASTER!I:I) -> Descontinuado (con stock)
A6: =+_xlfn.XLOOKUP(B6,MASTER!B:B,MASTER!C:C) -> LUCKY STRIKE ORIGINS RICH 20 PZ | B6: 75079888 | C6: =+_xlfn.XLOOKUP(B6,MASTER!B:B,MASTER!I:I) -> Descontinuado (con stock) | E6: =+_xlfn.XLOOKUP(F6,MASTER!B:B,MASTER!C:C) -> LUCKY STRIKE AMARILLOS 20S | F6: 75046521 | G6: =+_xlfn.XLOOKUP(F6,MASTER!B:B,MASTER!I:I) -> Activo
A7: =+_xlfn.XLOOKUP(B7,MASTER!B:B,MASTER!C:C) -> LUCKY STRIKE ORIGINS RICH 20 PZ | B7: 75079888 | C7: =+_xlfn.XLOOKUP(B7,MASTER!B:B,MASTER!I:I) -> Descontinuado (con stock) | E7: =+_xlfn.XLOOKUP(F7,MASTER!B:B,MASTER!C:C) -> LUCKY STRIKE CLICK 4 MIX | F7: 75051785 | G7: =+_xlfn.XLOOKUP(F7,MASTER!B:B,MASTER!I:I) -> Activo
A8: =+_xlfn.XLOOKUP(B8,MASTER!B:B,MASTER!C:C) -> LUCKY STRIKE ORIGINAL RED 20 PZ | B8: 75079956 | C8: =+_xlfn.XLOOKUP(B8,MASTER!B:B,MASTER!I:I) -> Descontinuado (con stock) | E8: =+_xlfn.XLOOKUP(F8,MASTER!B:B,MASTER!C:C) -> LUCKY STRIKE COMET 20S 1 CAJETILLA | F8: 75074227 | G8: =+_xlfn.XLOOKUP(F8,MASTER!B:B,MASTER!I:I) -> Activo
A9: =+_xlfn.XLOOKUP(B9,MASTER!B:B,MASTER!C:C) -> LUCKY STRIKE AMARILLOS 20S | B9: 75046521 | C9: =+_xlfn.XLOOKUP(B9,MASTER!B:B,MASTER!I:I) -> Activo | E9: =+_xlfn.XLOOKUP(F9,MASTER!B:B,MASTER!C:C) -> LUCKY STRIKE ENIGMA 100S 1PZ | F9: 75064716 | G9: =+_xlfn.XLOOKUP(F9,MASTER!B:B,MASTER!I:I) -> Activo
A10: =+_xlfn.XLOOKUP(B10,MASTER!B:B,MASTER!C:C) -> LUCKY STRIKE AMARILLOS 20S | B10: 75046521 | C10: =+_xlfn.XLOOKUP(B10,MASTER!B:B,MASTER!I:I) -> Activo | E10: =+_xlfn.XLOOKUP(F10,MASTER!B:B,MASTER!C:C) -> LUCKY STRIKE ORIGINAL FF 20S TUBE | F10: 75048129 | G10: =+_xlfn.XLOOKUP(F10,MASTER!B:B,MASTER!I:I) -> Activo
A11: =+_xlfn.XLOOKUP(B11,MASTER!B:B,MASTER!C:C) -> LUCKY STRIKE CLICK 4 MIX | B11: 75051785 | C11: =+_xlfn.XLOOKUP(B11,MASTER!B:B,MASTER!I:I) -> Activo | E11: =+_xlfn.XLOOKUP(F11,MASTER!B:B,MASTER!C:C) -> LUCKY STRIKE AMARILLOS 25S | F11: 75046545 | G11: =+_xlfn.XLOOKUP(F11,MASTER!B:B,MASTER!I:I) -> Activo
A12: =+_xlfn.XLOOKUP(B12,MASTER!B:B,MASTER!C:C) -> LUCKY STRIKE CLICK 4 MIX | B12: 75051785 | C12: =+_xlfn.XLOOKUP(B12,MASTER!B:B,MASTER!I:I) -> Activo | E12: =+_xlfn.XLOOKUP(F12,MASTER!B:B,MASTER!C:C) -> LUCKY STRIKE 20S ME TDC 1PZ | F12: 75063504 | G12: =+_xlfn.XLOOKUP(F12,MASTER!B:B,MASTER!I:I) -> Activo
A13: =+_xlfn.XLOOKUP(B13,MASTER!B:B,MASTER!C:C) -> LUCKY STRIKE COMET 20S 1 CAJETILLA | B13: 75074227 | C13: =+_xlfn.XLOOKUP(B13,MASTER!B:B,MASTER!I:I) -> Activo | E13: =+_xlfn.XLOOKUP(F13,MASTER!B:B,MASTER!C:C) -> MONTANA SHOTS 15S 1PZ | F13: 75064747 | G13: =+_xlfn.XLOOKUP(F13,MASTER!B:B,MASTER!I:I) -> Activo
A14: =+_xlfn.XLOOKUP(B14,MASTER!B:B,MASTER!C:C) -> LUCKY STRIKE COMET 20S 1 CAJETILLA | B14: 75074227 | C14: =+_xlfn.XLOOKUP(B14,MASTER!B:B,MASTER!I:I) -> Activo | E14: =+_xlfn.XLOOKUP(F14,MASTER!B:B,MASTER!C:C) -> PALL MALL XL ALASKA 15S 1 CAJETILLA | F14: 75074975 | G14: =+_xlfn.XLOOKUP(F14,MASTER!B:B,MASTER!I:I) -> Activo
... A46: =+_xlfn.XLOOKUP(B46,MASTER!B:B,MASTER!C:C) -> PALL MALL LONDON 20S 1 CAJETILLA | B46: 75076412 | C46: =+_xlfn.XLOOKUP(B46,MASTER!B:B,MASTER!I:I) -> Activo | E46: =+_xlfn.XLOOKUP(F46,MASTER!B:B,MASTER!C:C) -> PALL MALL PM MANILA DAYLIGHT 20 PZ | F46: 75083632 | G46: =+_xlfn.XLOOKUP(F46,MASTER!B:B,MASTER!I:I) -> Activo
A47: =+_xlfn.XLOOKUP(B47,MASTER!B:B,MASTER!C:C) -> PALL MALL XL MYKONO 15S 1 CAJETILLA | B47: 75074999 | C47: =+_xlfn.XLOOKUP(B47,MASTER!B:B,MASTER!I:I) -> Activo | E47: =+_xlfn.XLOOKUP(F47,MASTER!B:B,MASTER!C:C) -> #N/A | F47: 75084332 | G47: =+_xlfn.XLOOKUP(F47,MASTER!B:B,MASTER!I:I) -> #N/A
A48: =+_xlfn.XLOOKUP(B48,MASTER!B:B,MASTER!C:C) -> PALL MALL XL MYKONO 15S 1 CAJETILLA | B48: 75074999 | C48: =+_xlfn.XLOOKUP(B48,MASTER!B:B,MASTER!I:I) -> Activo
A49: =+_xlfn.XLOOKUP(B49,MASTER!B:B,MASTER!C:C) -> PALL MALL XL RÍO SU 20S 1 CAJETILLA | B49: 75074944 | C49: =+_xlfn.XLOOKUP(B49,MASTER!B:B,MASTER!I:I) -> Descontinuado (con stock)
A50: =+_xlfn.XLOOKUP(B50,MASTER!B:B,MASTER!C:C) -> PALL MALL XL RÍO SU 20S 1 CAJETILLA | B50: 75074944 | C50: =+_xlfn.XLOOKUP(B50,MASTER!B:B,MASTER!I:I) -> Descontinuado (con stock)
A51: =+_xlfn.XLOOKUP(B51,MASTER!B:B,MASTER!C:C) -> PALL MALL XL TOKYO 15S 1 CAJETILLA | B51: 75074982 | C51: =+_xlfn.XLOOKUP(B51,MASTER!B:B,MASTER!I:I) -> Activo
A52: =+_xlfn.XLOOKUP(B52,MASTER!B:B,MASTER!C:C) -> PALL MALL XL TOKYO 15S 1 CAJETILLA | B52: 75074982 | C52: =+_xlfn.XLOOKUP(B52,MASTER!B:B,MASTER!I:I) -> Activo
A53: =+_xlfn.XLOOKUP(B53,MASTER!B:B,MASTER!C:C) -> PALL MALL ALASKA DUSK 20 | B53: 75071295 | C53: =+_xlfn.XLOOKUP(B53,MASTER!B:B,MASTER!I:I) -> Activo
A54: =+_xlfn.XLOOKUP(B54,MASTER!B:B,MASTER!C:C) -> PALL MALL ALASKA DUSK 20 | B54: 75071295 | C54: =+_xlfn.XLOOKUP(B54,MASTER!B:B,MASTER!I:I) -> Activo
A55: =+_xlfn.XLOOKUP(B55,MASTER!B:B,MASTER!C:C) -> PALL MALL XL ATHENS 20S 1 CAJETILLA | B55: 75074913 | C55: =+_xlfn.XLOOKUP(B55,MASTER!B:B,MASTER!I:I) -> Descontinuado (con stock)
A56: =+_xlfn.XLOOKUP(B56,MASTER!B:B,MASTER!C:C) -> PALL MALL RED AND CLICK 20 | B56: 75027766 | C56: =+_xlfn.XLOOKUP(B56,MASTER!B:B,MASTER!I:I) -> Activo
A57: =+_xlfn.XLOOKUP(B57,MASTER!B:B,MASTER!C:C) -> PALL MALL RED AND CLICK 20 | B57: 75027766 | C57: =+_xlfn.XLOOKUP(B57,MASTER!B:B,MASTER!I:I) -> Activo
A58: =+_xlfn.XLOOKUP(B58,MASTER!B:B,MASTER!C:C) -> PALL MALL XL FUJI 20S 1 CAJETILLA | B58: 75074937 | C58: =+_xlfn.XLOOKUP(B58,MASTER!B:B,MASTER!I:I) -> Descontinuado (con stock)
A59: =+_xlfn.XLOOKUP(B59,MASTER!B:B,MASTER!C:C) -> PALL MALL XL FUJI 20S 1 CAJETILLA | B59: 75074937 | C59: =+_xlfn.XLOOKUP(B59,MASTER!B:B,MASTER!I:I) -> Descontinuado (con stock)
... A87: =+_xlfn.XLOOKUP(B87,MASTER!B:B,MASTER!C:C) -> PALL MALL PM MANILA DAYLIGHT 20 PZ | B87: 75083632 | C87: =+_xlfn.XLOOKUP(B87,MASTER!B:B,MASTER!I:I) -> Activo
A88: =+_xlfn.XLOOKUP(B88,MASTER!B:B,MASTER!C:C) -> #N/A | B88: 75084332 | C88: =+_xlfn.XLOOKUP(B88,MASTER!B:B,MASTER!I:I) -> #N/A

Sheet Hoja1
A1: ARTICULO | B1: UPC | C1: DESCRIPCIÓN | D1: PROVEEDOR | E1: FAMILIA | F1: SEGMENTO | G1: SABOR | H1: SUBCATEGORIA | I1: ESTATUS | J1: INNOVACION | K1: MERMA | L1: PERIODO | M1: ALCANCE
A2: 100024998 | B2: 7311250046988 | C2: ZYN SPEARMINT 6MG STRONG CAJETILLA PZ | D2: PMI | E2: ZYN | F2: ORAL | G2: F&S | H2: NICOTINE POUCHES | I2: Activo | J2: =+_xlfn.XLOOKUP(B2,INNOVACIÓN!A:A,INNOVACIÓN!B:B,"NO") -> NO | K2: =+_xlfn.XLOOKUP(B2,MERMA!B:B,MERMA!C:C,"No") -> No | L2: =+_xlfn.XLOOKUP(B2,MERMA!B:B,MERMA!D:D,"No es merma") -> No es merma
A3: 100024997 | B3: 7311250046971 | C3: ZYN SPEARMINT 3MG MEDIUM CAJETILLA PZ | D3: PMI | E3: ZYN | F3: ORAL | G3: F&S | H3: NICOTINE POUCHES | I3: Activo | J3: =+_xlfn.XLOOKUP(B3,INNOVACIÓN!A:A,INNOVACIÓN!B:B,"NO") -> NO | K3: =+_xlfn.XLOOKUP(B3,MERMA!B:B,MERMA!C:C,"No") -> No | L3: =+_xlfn.XLOOKUP(B3,MERMA!B:B,MERMA!D:D,"No es merma") -> No es merma
A4: 100025304 | B4: 7311250048388 | C4: ZYN SPEARMINIT 1.5MG LOW CAJETILLA PZ | D4: PMI | E4: ZYN | F4: ORAL | G4: F&S | H4: NICOTINE POUCHES | I4: Activo | J4: =+_xlfn.XLOOKUP(B4,INNOVACIÓN!A:A,INNOVACIÓN!B:B,"NO") -> NO | K4: =+_xlfn.XLOOKUP(B4,MERMA!B:B,MERMA!C:C,"No") -> No | L4: =+_xlfn.XLOOKUP(B4,MERMA!B:B,MERMA!D:D,"No es merma") -> No es merma
A5: 100026067 | B5: 7311250035579 | C5: ZYN PEACH 6MG STRONG LATA PZ | D5: PMI | E5: ZYN | F5: ORAL | G5: F&S | H5: NICOTINE POUCHES | I5: Activo | J5: =+_xlfn.XLOOKUP(B5,INNOVACIÓN!A:A,INNOVACIÓN!B:B,"NO") -> NO | K5: =+_xlfn.XLOOKUP(B5,MERMA!B:B,MERMA!C:C,"No") -> No | L5: =+_xlfn.XLOOKUP(B5,MERMA!B:B,MERMA!D:D,"No es merma") -> No es merma
A6: 100026065 | B6: 7311250035593 | C6: ZYN PEACH 3MG MEDIUM LATA PZ | D6: PMI | E6: ZYN | F6: ORAL | G6: F&S | H6: NICOTINE POUCHES | I6: Activo | J6: =+_xlfn.XLOOKUP(B6,INNOVACIÓN!A:A,INNOVACIÓN!B:B,"NO") -> NO | K6: =+_xlfn.XLOOKUP(B6,MERMA!B:B,MERMA!C:C,"No") -> No | L6: =+_xlfn.XLOOKUP(B6,MERMA!B:B,MERMA!D:D,"No es merma") -> No es merma
A7: 100024400 | B7: 7311250044441 | C7: ZYN ESPRESSINO MINI STRONG UNIDAD PZ | D7: PMI | E7: BYE | F7: ORAL | G7: F&S | H7: NICOTINE POUCHES | I7: Descontinuado (con stock) | J7: =+_xlfn.XLOOKUP(B7,INNOVACIÓN!A:A,INNOVACIÓN!B:B,"NO") -> NO | K7: =+_xlfn.XLOOKUP(B7,MERMA!B:B,MERMA!C:C,"No") -> No | L7: =+_xlfn.XLOOKUP(B7,MERMA!B:B,MERMA!D:D,"No es merma") -> No es merma
A8: 100024295 | B8: 7311250044434 | C8: ZYN ESPRESSINO MINI MEDIUM CAJETILLA PZ | D8: PMI | E8: BYE | F8: ORAL | G8: F&S | H8: NICOTINE POUCHES | I8: Descontinuado (con stock) | J8: =+_xlfn.XLOOKUP(B8,INNOVACIÓN!A:A,INNOVACIÓN!B:B,"NO") -> NO | K8: =+_xlfn.XLOOKUP(B8,MERMA!B:B,MERMA!C:C,"No") -> No | L8: =+_xlfn.XLOOKUP(B8,MERMA!B:B,MERMA!D:D,"No es merma") -> No es merma
A9: 100024399 | B9: 7311250044403 | C9: ZYN COOL MINT MINI STRONG UNIDAD PZ | D9: PMI | E9: ZYN | F9: ORAL | G9: F&S | H9: NICOTINE POUCHES | I9: Activo | J9: =+_xlfn.XLOOKUP(B9,INNOVACIÓN!A:A,INNOVACIÓN!B:B,"NO") -> NO | K9: =+_xlfn.XLOOKUP(B9,MERMA!B:B,MERMA!C:C,"No") -> No | L9: =+_xlfn.XLOOKUP(B9,MERMA!B:B,MERMA!D:D,"No es merma") -> No es merma
A10: 100024294 | B10: 7311250044397 | C10: ZYN COOL MINT MINI MEDIUM CAJETILLA PZ | D10: PMI | E10: ZYN | F10: ORAL | G10: F&S | H10: NICOTINE POUCHES | I10: Activo | J10: =+_xlfn.XLOOKUP(B10,INNOVACIÓN!A:A,INNOVACIÓN!B:B,"NO") -> NO | K10: =+_xlfn.XLOOKUP(B10,MERMA!B:B,MERMA!C:C,"No") -> No | L10: =+_xlfn.XLOOKUP(B10,MERMA!B:B,MERMA!D:D,"No es merma") -> No es merma
A11: 100026064 | B11: 7311250035562 | C11: ZYN COOL MINT 1.5MG LOW LATA PZ | D11: PMI | E11: ZYN | F11: ORAL | G11: F&S | H11: NICOTINE POUCHES | I11: Activo | J11: =+_xlfn.XLOOKUP(B11,INNOVACIÓN!A:A,INNOVACIÓN!B:B,"NO") -> NO | K11: =+_xlfn.XLOOKUP(B11,MERMA!B:B,MERMA!C:C,"No") -> No | L11: =+_xlfn.XLOOKUP(B11,MERMA!B:B,MERMA!D:D,"No es merma") -> No es merma
A12: 100024398 | B12: 7311250044427 | C12: ZYN CITRUS MINI STRONG UNIDAD PZ | D12: PMI | E12: ZYN | F12: ORAL | G12: F&S | H12: NICOTINE POUCHES | I12: Activo | J12: =+_xlfn.XLOOKUP(B12,INNOVACIÓN!A:A,INNOVACIÓN!B:B,"NO") -> NO | K12: =+_xlfn.XLOOKUP(B12,MERMA!B:B,MERMA!C:C,"No") -> No | L12: =+_xlfn.XLOOKUP(B12,MERMA!B:B,MERMA!D:D,"No es merma") -> No es merma
A13: 100024293 | B13: 7311250044410 | C13: ZYN CITRUS MINI MEDIUM CAJETILLA PZ | D13: PMI | E13: ZYN | F13: ORAL | G13: F&S | H13: NICOTINE POUCHES | I13: Activo | J13: =+_xlfn.XLOOKUP(B13,INNOVACIÓN!A:A,INNOVACIÓN!B:B,"NO") -> NO | K13: =+_xlfn.XLOOKUP(B13,MERMA!B:B,MERMA!C:C,"No") -> No | L13: =+_xlfn.XLOOKUP(B13,MERMA!B:B,MERMA!D:D,"No es merma") -> No es merma
... A29: 100012997 | B29: 75064716 | C29: LUCKY STRIKE ENIGMA 100S 1PZ | D29: BAT | E29: LUCKY STRIKE | F29: VFM | G29: F&S | H29: CIGARROS | I29: Activo | J29: =+_xlfn.XLOOKUP(B29,INNOVACIÓN!A:A,INNOVACIÓN!B:B,"NO") -> NO | K29: =+_xlfn.XLOOKUP(B29,MERMA!B:B,MERMA!C:C,"No") -> No | L29: =+_xlfn.XLOOKUP(B29,MERMA!B:B,MERMA!D:D,"No es merma") -> No es merma
A30: 100026068 | B30: 75084332 | C30: LUCKY STRIKE LUCKIES STICK 20S 20 PZ | D30: BAT | E30: BYE | F30: VFM | H30: CIGARROS | I30: Descontinuado (con stock) | J30: =+_xlfn.XLOOKUP(B30,INNOVACIÓN!A:A,INNOVACIÓN!B:B,"NO") -> NO | K30: =+_xlfn.XLOOKUP(B30,MERMA!B:B,MERMA!C:C,"No") -> SI | L30: =+_xlfn.XLOOKUP(B30,MERMA!B:B,MERMA!D:D,"No es merma") -> 2026 H1
A31: 100011590 | B31: 7501031700028 | C31: LUCKY STRIKE OR255 PPROMO 1PZ | D31: BAT | E31: LUCKY STRIKE | F31: PREMIUM | G31: FF | H31: CIGARROS | I31: Activo | J31: =+_xlfn.XLOOKUP(B31,INNOVACIÓN!A:A,INNOVACIÓN!B:B,"NO") -> NO | K31: =+_xlfn.XLOOKUP(B31,MERMA!B:B,MERMA!C:C,"No") -> No | L31: =+_xlfn.XLOOKUP(B31,MERMA!B:B,MERMA!D:D,"No es merma") -> No es merma
A32: 100080975 | B32: 75048129 | C32: LUCKY STRIKE ORIGINAL FF 20S TUBE | D32: BAT | E32: LUCKY STRIKE | F32: VFM | G32: FULL FLAVOR | H32: CIGARROS | I32: Activo | J32: =+_xlfn.XLOOKUP(B32,INNOVACIÓN!A:A,INNOVACIÓN!B:B,"NO") -> NO | K32: =+_xlfn.XLOOKUP(B32,MERMA!B:B,MERMA!C:C,"No") -> No | L32: =+_xlfn.XLOOKUP(B32,MERMA!B:B,MERMA!D:D,"No es merma") -> No es merma
A33: 100020970 | B33: 75076405 | C33: MONTANA CLASSI 14S 1 CAJETILLA | D33: BAT | E33: MONTANA | F33: Bajo-UL | G33: FULL FLAVOR | H33: CIGARROS | I33: Activo | J33: =+_xlfn.XLOOKUP(B33,INNOVACIÓN!A:A,INNOVACIÓN!B:B,"NO") -> NO | K33: =+_xlfn.XLOOKUP(B33,MERMA!B:B,MERMA!C:C,"No") -> No | L33: =+_xlfn.XLOOKUP(B33,MERMA!B:B,MERMA!D:D,"No es merma") -> No es merma
A34: 100020969 | B34: 75076740 | C34: MONTANA CLASSI 20S 1 CAJETILLA | D34: BAT | E34: MONTANA | F34: Bajo-UL | G34: FULL FLAVOR | H34: CIGARROS | I34: Activo | J34: =+_xlfn.XLOOKUP(B34,INNOVACIÓN!A:A,INNOVACIÓN!B:B,"NO") -> NO | K34: =+_xlfn.XLOOKUP(B34,MERMA!B:B,MERMA!C:C,"No") -> No | L34: =+_xlfn.XLOOKUP(B34,MERMA!B:B,MERMA!D:D,"No es merma") -> No es merma
A35: 100013075 | B35: 75064747 | C35: MONTANA SHOTS 15S 1PZ | D35: BAT | E35: MONTANA | F35: LOW | G35: FULL FLAVOR | H35: CIGARROS | I35: Activo | J35: =+_xlfn.XLOOKUP(B35,INNOVACIÓN!A:A,INNOVACIÓN!B:B,"NO") -> NO | K35: =+_xlfn.XLOOKUP(B35,MERMA!B:B,MERMA!C:C,"No") -> No | L35: =+_xlfn.XLOOKUP(B35,MERMA!B:B,MERMA!D:D,"No es merma") -> No es merma
A36: 100013892 | B36: 75064754 | C36: MONTANA SHOTS 1PZ | D36: BAT | E36: MONTANA | F36: LOW | G36: FULL FLAVOR | H36: CIGARROS | I36: Activo | J36: =+_xlfn.XLOOKUP(B36,INNOVACIÓN!A:A,INNOVACIÓN!B:B,"NO") -> NO | K36: =+_xlfn.XLOOKUP(B36,MERMA!B:B,MERMA!C:C,"No") -> No | L36: =+_xlfn.XLOOKUP(B36,MERMA!B:B,MERMA!D:D,"No es merma") -> No es merma
A37: 100023317 | B37: 75078843 | C37: MONTANA SHOTS CLASSICS 25 PZ | D37: BAT | E37: MONTANA | F37: Bajo-UL | G37: FULL FLAVOR | H37: CIGARROS | I37: Activo | J37: =+_xlfn.XLOOKUP(B37,INNOVACIÓN!A:A,INNOVACIÓN!B:B,"NO") -> NO | K37: =+_xlfn.XLOOKUP(B37,MERMA!B:B,MERMA!C:C,"No") -> No | L37: =+_xlfn.XLOOKUP(B37,MERMA!B:B,MERMA!D:D,"No es merma") -> No es merma
A38: 100016489 | B38: 75071301 | C38: PALL MALL ALASKA DUSK 15 | D38: BAT | E38: BYE | F38: VFM | G38: MENTHOL | H38: CIGARROS | I38: Activo | J38: =+_xlfn.XLOOKUP(B38,INNOVACIÓN!A:A,INNOVACIÓN!B:B,"NO") -> NO | K38: =+_xlfn.XLOOKUP(B38,MERMA!B:B,MERMA!C:C,"No") -> No | L38: =+_xlfn.XLOOKUP(B38,MERMA!B:B,MERMA!D:D,"No es merma") -> No es merma
A39: 100016443 | B39: 75071295 | C39: PALL MALL ALASKA DUSK 20 | D39: BAT | E39: PALL MALL | F39: VFM | G39: MENTHOL | H39: CIGARROS | I39: Activo | J39: =+_xlfn.XLOOKUP(B39,INNOVACIÓN!A:A,INNOVACIÓN!B:B,"NO") -> NO | K39: =+_xlfn.XLOOKUP(B39,MERMA!B:B,MERMA!C:C,"No") -> No | L39: =+_xlfn.XLOOKUP(B39,MERMA!B:B,MERMA!D:D,"No es merma") -> No es merma
A40: 100026387 | B40: 75080501 | C40: PALL MALL ARUBA 20 PZ | D40: BAT | E40: PALL MALL | F40: Medio-Bajo | G40: LOW-TAR | H40: CIGARROS | I40: Activo | J40: =+_xlfn.XLOOKUP(B40,INNOVACIÓN!A:A,INNOVACIÓN!B:B,"NO") -> NO | K40: =+_xlfn.XLOOKUP(B40,MERMA!B:B,MERMA!C:C,"No") -> No | L40: =+_xlfn.XLOOKUP(B40,MERMA!B:B,MERMA!D:D,"No es merma") -> No es merma
A41: 101000079 | B41: 75079017 | C41: PALL MALL BORA BORA SUNBREAK 20 PZ | D41: BAT | E41: PALL MALL | F41: VFM | G41: F&S | H41: CIGARROS | I41: Activo | J41: =+_xlfn.XLOOKUP(B41,INNOVACIÓN!A:A,INNOVACIÓN!B:B,"NO") -> NO | K41: =+_xlfn.XLOOKUP(B41,MERMA!B:B,MERMA!C:C,"No") -> No | L41: =+_xlfn.XLOOKUP(B41,MERMA!B:B,MERMA!D:D,"No es merma") -> No es merma
A42: 100025311 | B42: 75083656 | C42: TEREA TWILIGHT PEARL 20 CAJETILLA PZ | D42: PMI | E42: TEREA | F42: LOW | G42: HTP FLAVOUR | H42: HTP | I42: Activo | J42: =+_xlfn.XLOOKUP(B42,INNOVACIÓN!A:A,INNOVACIÓN!B:B,"NO") -> NO | K42: =+_xlfn.XLOOKUP(B42,MERMA!B:B,MERMA!C:C,"No") -> No | L42: =+_xlfn.XLOOKUP(B42,MERMA!B:B,MERMA!D:D,"No es merma") -> No es merma
... A532: 100026616 | B532: 7622100511038 | C532: IQOS ILUMA I BREEZE BLUE PZ | D532: PMI | E532: IQOS | F532: HTP | G532: NA | H532: HTP | I532: Activo | J532: =+_xlfn.XLOOKUP(B532,INNOVACIÓN!A:A,INNOVACIÓN!B:B,"NO") -> NO | K532: =+_xlfn.XLOOKUP(B532,MERMA!B:B,MERMA!C:C,"No") -> No | L532: =+_xlfn.XLOOKUP(B532,MERMA!B:B,MERMA!D:D,"No es merma") -> No es merma
A533: 100026687 | B533: 75084585 | C533: PALL MALL AIRLINES ALASKA 20 PZ | D533: BAT | E533: BYE | F533: VFM | H533: CIGARROS | I533: Activo | J533: =+_xlfn.XLOOKUP(B533,INNOVACIÓN!A:A,INNOVACIÓN!B:B,"NO") -> NO | K533: =+_xlfn.XLOOKUP(B533,MERMA!B:B,MERMA!C:C,"No") -> No | L533: =+_xlfn.XLOOKUP(B533,MERMA!B:B,MERMA!D:D,"No es merma") -> No es merma
A534: 100026688 | B534: 75084608 | C534: PALL MALL AIRLINES TOKYO 20 PZ | D534: BAT | E534: BYE | F534: VFM | H534: CIGARROS | I534: Activo | J534: =+_xlfn.XLOOKUP(B534,INNOVACIÓN!A:A,INNOVACIÓN!B:B,"NO") -> NO | K534: =+_xlfn.XLOOKUP(B534,MERMA!B:B,MERMA!C:C,"No") -> No | L534: =+_xlfn.XLOOKUP(B534,MERMA!B:B,MERMA!D:D,"No es merma") -> No es merma
A535: 100026689 | B535: 75084592 | C535: PALL MALL AIRLINES MYKONOS 20 PZ | D535: BAT | E535: BYE | F535: VFM | H535: CIGARROS | I535: Activo | J535: =+_xlfn.XLOOKUP(B535,INNOVACIÓN!A:A,INNOVACIÓN!B:B,"NO") -> NO | K535: =+_xlfn.XLOOKUP(B535,MERMA!B:B,MERMA!C:C,"No") -> No | L535: =+_xlfn.XLOOKUP(B535,MERMA!B:B,MERMA!D:D,"No es merma") -> No es merma
A536: 100026690 | B536: 75084646 | C536: PALL MALL AIRLINES HAWAII 20 PZ | D536: BAT | E536: BYE | F536: VFM | H536: CIGARROS | I536: Activo | J536: =+_xlfn.XLOOKUP(B536,INNOVACIÓN!A:A,INNOVACIÓN!B:B,"NO") -> NO | K536: =+_xlfn.XLOOKUP(B536,MERMA!B:B,MERMA!C:C,"No") -> No | L536: =+_xlfn.XLOOKUP(B536,MERMA!B:B,MERMA!D:D,"No es merma") -> No es merma
A537: 100026691 | B537: 75084639 | C537: PALL MALL AIRLINES BORA BORA 20 PZ | D537: BAT | E537: BYE | F537: VFM | H537: CIGARROS | I537: Activo | J537: =+_xlfn.XLOOKUP(B537,INNOVACIÓN!A:A,INNOVACIÓN!B:B,"NO") -> NO | K537: =+_xlfn.XLOOKUP(B537,MERMA!B:B,MERMA!C:C,"No") -> No | L537: =+_xlfn.XLOOKUP(B537,MERMA!B:B,MERMA!D:D,"No es merma") -> No es merma
A538: 100026692 | B538: 75084653 | C538: PALL MALL AIRLINES MANILA 20 PZ | D538: BAT | E538: BYE | F538: VFM | H538: CIGARROS | I538: Activo | J538: =+_xlfn.XLOOKUP(B538,INNOVACIÓN!A:A,INNOVACIÓN!B:B,"NO") -> NO | K538: =+_xlfn.XLOOKUP(B538,MERMA!B:B,MERMA!C:C,"No") -> No | L538: =+_xlfn.XLOOKUP(B538,MERMA!B:B,MERMA!D:D,"No es merma") -> No es merma
A539: 100026676 | B539: 75087142 | C539: PALL MALL SUMMER ALASKA 20 PZ | D539: BAT | E539: BYE | F539: PREMIUM | H539: CIGARROS | I539: Activo | J539: =+_xlfn.XLOOKUP(B539,INNOVACIÓN!A:A,INNOVACIÓN!B:B,"NO") -> SI | K539: =+_xlfn.XLOOKUP(B539,MERMA!B:B,MERMA!C:C,"No") -> No | L539: =+_xlfn.XLOOKUP(B539,MERMA!B:B,MERMA!D:D,"No es merma") -> No es merma
A540: 100026677 | B540: 75087159 | C540: PALL MALL SUMMER TOKYO 20 PZ | D540: BAT | E540: BYE | F540: PREMIUM | H540: CIGARROS | I540: Activo | J540: =+_xlfn.XLOOKUP(B540,INNOVACIÓN!A:A,INNOVACIÓN!B:B,"NO") -> SI | K540: =+_xlfn.XLOOKUP(B540,MERMA!B:B,MERMA!C:C,"No") -> No | L540: =+_xlfn.XLOOKUP(B540,MERMA!B:B,MERMA!D:D,"No es merma") -> No es merma
A541: 100026678 | B541: 75087166 | C541: PALL MALL SUMMER MYKONOS 20 PZ | D541: BAT | E541: BYE | F541: PREMIUM | H541: CIGARROS | I541: Activo | J541: =+_xlfn.XLOOKUP(B541,INNOVACIÓN!A:A,INNOVACIÓN!B:B,"NO") -> SI | K541: =+_xlfn.XLOOKUP(B541,MERMA!B:B,MERMA!C:C,"No") -> No | L541: =+_xlfn.XLOOKUP(B541,MERMA!B:B,MERMA!D:D,"No es merma") -> No es merma
A542: 100026679 | B542: 75087173 | C542: PALL MALL SUMMER HAWAII 20 PZ | D542: BAT | E542: BYE | F542: PREMIUM | H542: CIGARROS | I542: Activo | J542: =+_xlfn.XLOOKUP(B542,INNOVACIÓN!A:A,INNOVACIÓN!B:B,"NO") -> SI | K542: =+_xlfn.XLOOKUP(B542,MERMA!B:B,MERMA!C:C,"No") -> No | L542: =+_xlfn.XLOOKUP(B542,MERMA!B:B,MERMA!D:D,"No es merma") -> No es merma
A543: 100026680 | B543: 75087180 | C543: PALL MALL SUMMER MANILA 20 PZ | D543: BAT | E543: BYE | F543: PREMIUM | H543: CIGARROS | I543: Activo | J543: =+_xlfn.XLOOKUP(B543,INNOVACIÓN!A:A,INNOVACIÓN!B:B,"NO") -> SI | K543: =+_xlfn.XLOOKUP(B543,MERMA!B:B,MERMA!C:C,"No") -> No | L543: =+_xlfn.XLOOKUP(B543,MERMA!B:B,MERMA!D:D,"No es merma") -> No es merma
A544: 100026684 | B544: 75084493 | C544: PALL MALL AMALFI 20 PZ | D544: BAT | E544: PALL MALL | F544: Medio-Bajo | H544: CIGARROS | I544: Activo | J544: =+_xlfn.XLOOKUP(B544,INNOVACIÓN!A:A,INNOVACIÓN!B:B,"NO") -> SI | K544: =+_xlfn.XLOOKUP(B544,MERMA!B:B,MERMA!C:C,"No") -> No | L544: =+_xlfn.XLOOKUP(B544,MERMA!B:B,MERMA!D:D,"No es merma") -> No es merma
...

Sheet MERMA
A1: DESCRIPCIÓN | B1: UPC | C1: MERMA | D1: PERIODO | E1: Alcance
A2: CAMEL CIGARR FF CD CAJET | B2: 8308315 | C2: SI | D2: 2025 | E2: Nacional
A3: CAMEL CIGARR 14S FF CD CAJET | B3: 8338918 | C3: SI | D3: 2025 | E3: Nacional
A4: WINSTON CIGARR BLUE 14S CAJET | B4: 40331379 | C4: SI | D4: 2025 | E4: Nacional
A5: BENSON&HEDGE CIGARR CS CAJET | B5: 75001254 | C5: SI | D5: 2025 | E5: Nacional
A6: MARLBORO CIGARR LIGTH EL CS CAJET | B6: 75001292 | C6: SI | D6: 2025 | E6: Nacional
A7: MARLBORO SELECC ARTESANAL 14 1 CAJETILLA | B7: 75001414 | C7: SI | D7: 2025 | E7: Nacional
A8: MARLBORO VISTA ARTIC 14S CAJETILLAPZ | B8: 75004408 | C8: SI | D8: 2025 | E8: Nacional
A9: MARLBORO EXOTIC VISTA EXOTIC 1 CAJETILLA | B9: 75004415 | C9: SI | D9: 2025 | E9: Nacional
A10: MARLBORO CARIBBEAN FUSION 100 BOX 14 CAJETILLA PZ | B10: 75006204 | C10: SI | D10: 2025 | E10: Nacional
A11: TEREA GREEN ZING CAJETILLA PZ | B11: 75006341 | C11: SI | D11: 2025 | E11: Nacional
A12: MARLBORO LUNA SHUFFLE 100 BOX 20 STD CAJETILLA PZ | B12: 75006587 | C12: SI | D12: 2025 | E12: Nacional
A13: TEREA PURPLE CAJETILLA PZ | B13: 75006952 | C13: SI | D13: 2025 | E13: Nacional
... A103: IQOS HISOPO GLICERINA 1 CAJETILLA | B103: 7622100711049 | C103: SI | D103: 2025 | E103: Nacional
A104: LUCKIE STRIKE BLOND INFUSE 20S FF | B104: 75062675 | C104: SI | D104: 2026 H1
A105: LUCKIES 20S | B105: 75081942 | C105: SI | D105: 2026 H1 | E105: México, Quintana Roo
A106: LUCKIES 25S | B106: 75080679 | C106: SI | D106: 2026 H1 | E106: México, Puebla y Quintana Roo
A107: LUCKY STRIKE 94MM SUNSHINE BLAST 1 CAJETILLA | B107: 75067878 | C107: SI | D107: 2026 H1
A108: LUCKY STRIKE 94MM WINTER STORM 1 CAJETILLA | B108: 75070373 | C108: SI | D108: 2026 H1
A109: LUCKY STRIKE LATA CLÁSICA RED 20 PZ | B109: 75080105 | C109: SI | D109: 2026 H1
A110: LUCKY STRIKE LUCKIES STICK 20S 20 PZ | B110: 75084332 | C110: SI | D110: 2026 H1 | E110: México y Quintana Roo
A111: LUCKY STRIKE NOVA LATA 1 CAJETILLA | B111: 75073978 | C111: SI | D111: 2026 H1
A112: LUCKY STRIKE ORIGINAL RED 20 PZ | B112: 75079956 | C112: SI | D112: 2026 H1
A113: PALL MALL CLASSICS 20 | B113: 75071776 | C113: SI | D113: 2026 H1 | E113: México
A114: PALL MALL CLASSICS 25 PZ | B114: 75079963 | C114: SI | D114: 2026 H1 | E114: México
A115: PALL MALL EX CLASSI 14S 1 CAJETILLA | B115: 75074081 | C115: SI | D115: 2026 H1 | E115: México
A116: PALL MALL EX RED 15 1 CAJETILLA | B116: 75073534 | C116: SI | D116: 2026 H1 | E116: México, Puebla y Quintana Roo
A117: PALL MALL MIAMI STRESS RELIEVER 20 PZ | B117: 75083977 | C117: SI | D117: 2026 H1 | E117: Yucatán
A118: PALL MALL MIX PACK 20 | B118: 75070090 | C118: SI | D118: 2026 H1 | E118: México, Quintana Roo y Yucatán
A119: PALL MALL RED 25 1PZ | B119: 75064778 | C119: SI | D119: 2026 H1 | E119: México, Quintana y Yucatán
A120: PALL MALL XL MIAMI PARADISE 20S 20 PZ | B120: 75081058 | C120: SI | D120: 2026 H1
A121: PALL MALL XL RÍO SU 20S 1 CAJETILLA | B121: 75074944 | C121: SI | D121: 2026 H1 | E121: México y Quintana Roo

Sheet Hoja5
A1: UPC | B1: ARTICULO | C1: DESCRIPCIÓN | D1: PROVEEDOR | E1: ESTATUS | G1: UPC | H1: ARTICULO | I1: DESCRIPCIÓN | J1: PROVEEDOR | K1: ESTATUS | N1: UPC | O1: SKU | P1: DESCRIPCIÓN | Q1: PROVEEDOR | R1: ESTATUS | S1: Devolución
A2: 2168 | B2: =+_xlfn.XLOOKUP(A2,MASTER!B:B,MASTER!A:A) -> 100080353 | C2: =+_xlfn.XLOOKUP(A2,MASTER!B:B,MASTER!C:C) -> LAGUNAS PURO C/5 PZAS CAJET | D2: =+_xlfn.XLOOKUP(A2,MASTER!B:B,MASTER!D:D) -> PUROS | E2: =+_xlfn.XLOOKUP(A2,MASTER!B:B,MASTER!I:I) -> Activo | G2: 9872 | H2: =+_xlfn.XLOOKUP(G2,MASTER!B:B,MASTER!A:A) -> 100009965 | I2: =+_xlfn.XLOOKUP(G2,MASTER!B:B,MASTER!C:C) -> TOKIO MIDNIGHT PALL MALL 20PZ | N2: 8346917 | O2: =+_xlfn.XLOOKUP(N2,MASTER!B:B,MASTER!A:A) -> 100080644 | P2: =+_xlfn.XLOOKUP(N2,MASTER!B:B,MASTER!C:C) -> PALL MALL WHITE AND CLICK 20 | Q2: =+_xlfn.XLOOKUP(N2,MASTER!B:B,MASTER!D:D) -> BAT | R2: =+_xlfn.XLOOKUP(N2,MASTER!B:B,MASTER!I:I) -> Activo | S2: =+_xlfn.XLOOKUP(N2,$U$2:$U$16,$V$2:$V$16,"no") -> no | U2: 75074944 | V2: si}
A3: 2169 | B3: =+_xlfn.XLOOKUP(A3,MASTER!B:B,MASTER!A:A) -> #N/A | C3: =+_xlfn.XLOOKUP(A3,MASTER!B:B,MASTER!C:C) -> #N/A | D3: =+_xlfn.XLOOKUP(A3,MASTER!B:B,MASTER!D:D) -> #N/A | E3: =+_xlfn.XLOOKUP(A3,MASTER!B:B,MASTER!I:I) -> #N/A | G3: 8346917 | H3: =+_xlfn.XLOOKUP(G3,MASTER!B:B,MASTER!A:A) -> 100080644 | I3: =+_xlfn.XLOOKUP(G3,MASTER!B:B,MASTER!C:C) -> PALL MALL WHITE AND CLICK 20 | N3: 75027766 | O3: =+_xlfn.XLOOKUP(N3,MASTER!B:B,MASTER!A:A) -> 100080802 | P3: =+_xlfn.XLOOKUP(N3,MASTER!B:B,MASTER!C:C) -> PALL MALL RED AND CLICK 20 | Q3: =+_xlfn.XLOOKUP(N3,MASTER!B:B,MASTER!D:D) -> BAT | R3: =+_xlfn.XLOOKUP(N3,MASTER!B:B,MASTER!I:I) -> Activo | S3: =+_xlfn.XLOOKUP(N3,$U$2:$U$16,$V$2:$V$16,"no") -> no | U3: 75081942 | V3: si}
A4: 2712 | B4: =+_xlfn.XLOOKUP(A4,MASTER!B:B,MASTER!A:A) -> #N/A | C4: =+_xlfn.XLOOKUP(A4,MASTER!B:B,MASTER!C:C) -> #N/A | D4: =+_xlfn.XLOOKUP(A4,MASTER!B:B,MASTER!D:D) -> #N/A | E4: =+_xlfn.XLOOKUP(A4,MASTER!B:B,MASTER!I:I) -> #N/A | G4: 75001254 | H4: =+_xlfn.XLOOKUP(G4,MASTER!B:B,MASTER!A:A) -> 100080031 | I4: =+_xlfn.XLOOKUP(G4,MASTER!B:B,MASTER!C:C) -> BENSON&HEDGE CIGARR CS CAJET | N4: 75046521 | O4: =+_xlfn.XLOOKUP(N4,MASTER!B:B,MASTER!A:A) -> 100080955 | P4: =+_xlfn.XLOOKUP(N4,MASTER!B:B,MASTER!C:C) -> LUCKY STRIKE AMARILLOS 20S | Q4: =+_xlfn.XLOOKUP(N4,MASTER!B:B,MASTER!D:D) -> BAT | R4: =+_xlfn.XLOOKUP(N4,MASTER!B:B,MASTER!I:I) -> Activo | S4: =+_xlfn.XLOOKUP(N4,$U$2:$U$16,$V$2:$V$16,"no") -> no | U4: 75080105 | V4: si}
A5: 10000 | B5: =+_xlfn.XLOOKUP(A5,MASTER!B:B,MASTER!A:A) -> 100011025 | C5: =+_xlfn.XLOOKUP(A5,MASTER!B:B,MASTER!C:C) -> MARLBORO CIGARR ROJO CD CAJET | D5: =+_xlfn.XLOOKUP(A5,MASTER!B:B,MASTER!D:D) -> PMI | E5: =+_xlfn.XLOOKUP(A5,MASTER!B:B,MASTER!I:I) -> Inactivo | G5: 75001292 | H5: =+_xlfn.XLOOKUP(G5,MASTER!B:B,MASTER!A:A) -> 100080029 | I5: =+_xlfn.XLOOKUP(G5,MASTER!B:B,MASTER!C:C) -> MARLBORO CIGARR LIGTH EL CS CAJET | N5: 75046545 | O5: =+_xlfn.XLOOKUP(N5,MASTER!B:B,MASTER!A:A) -> 100080952 | P5: =+_xlfn.XLOOKUP(N5,MASTER!B:B,MASTER!C:C) -> LUCKY STRIKE AMARILLOS 25S | Q5: =+_xlfn.XLOOKUP(N5,MASTER!B:B,MASTER!D:D) -> BAT | R5: =+_xlfn.XLOOKUP(N5,MASTER!B:B,MASTER!I:I) -> Activo | S5: =+_xlfn.XLOOKUP(N5,$U$2:$U$16,$V$2:$V$16,"no") -> no | U5: 75080679 | V5: si}
A6: 10578 | B6: =+_xlfn.XLOOKUP(A6,MASTER!B:B,MASTER!A:A) -> #N/A | C6: =+_xlfn.XLOOKUP(A6,MASTER!B:B,MASTER!C:C) -> #N/A | D6: =+_xlfn.XLOOKUP(A6,MASTER!B:B,MASTER!D:D) -> #N/A | E6: =+_xlfn.XLOOKUP(A6,MASTER!B:B,MASTER!I:I) -> #N/A | G6: 75001315 | H6: =+_xlfn.XLOOKUP(G6,MASTER!B:B,MASTER!A:A) -> 100080028 | I6: =+_xlfn.XLOOKUP(G6,MASTER!B:B,MASTER!C:C) -> MARLBORO CIGARR ROJO CL CS CAJET | N6: 75048129 | O6: =+_xlfn.XLOOKUP(N6,MASTER!B:B,MASTER!A:A) -> 100080975 | P6: =+_xlfn.XLOOKUP(N6,MASTER!B:B,MASTER!C:C) -> LUCKY STRIKE ORIGINAL FF 20S TUBE | Q6: =+_xlfn.XLOOKUP(N6,MASTER!B:B,MASTER!D:D) -> BAT | R6: =+_xlfn.XLOOKUP(N6,MASTER!B:B,MASTER!I:I) -> Activo | S6: =+_xlfn.XLOOKUP(N6,$U$2:$U$16,$V$2:$V$16,"no") -> no | U6: 75084332 | V6: si}
A7: 8346917 | B7: =+_xlfn.XLOOKUP(A7,MASTER!B:B,MASTER!A:A) -> 100080644 | C7: =+_xlfn.XLOOKUP(A7,MASTER!B:B,MASTER!C:C) -> PALL MALL WHITE AND CLICK 20 | D7: =+_xlfn.XLOOKUP(A7,MASTER!B:B,MASTER!D:D) -> BAT | E7: =+_xlfn.XLOOKUP(A7,MASTER!B:B,MASTER!I:I) -> Activo | G7: 75001322 | H7: =+_xlfn.XLOOKUP(G7,MASTER!B:B,MASTER!A:A) -> 100080027 | I7: =+_xlfn.XLOOKUP(G7,MASTER!B:B,MASTER!C:C) -> MARLBORO CIGARR ROJO CD CAJET | N7: 75051785 | O7: =+_xlfn.XLOOKUP(N7,MASTER!B:B,MASTER!A:A) -> 100004788 | P7: =+_xlfn.XLOOKUP(N7,MASTER!B:B,MASTER!C:C) -> LUCKY STRIKE CLICK 4 MIX | Q7: =+_xlfn.XLOOKUP(N7,MASTER!B:B,MASTER!D:D) -> BAT | R7: =+_xlfn.XLOOKUP(N7,MASTER!B:B,MASTER!I:I) -> Activo | S7: =+_xlfn.XLOOKUP(N7,$U$2:$U$16,$V$2:$V$16,"no") -> no | U7: 75079956 | V7: si}
A8: 40331362 | B8: =+_xlfn.XLOOKUP(A8,MASTER!B:B,MASTER!A:A) -> 100080896 | C8: =+_xlfn.XLOOKUP(A8,MASTER!B:B,MASTER!C:C) -> WINSTON CIGARR CLASSIC 14S CAJET | D8: =+_xlfn.XLOOKUP(A8,MASTER!B:B,MASTER!D:D) -> JTI | E8: =+_xlfn.XLOOKUP(A8,MASTER!B:B,MASTER!I:I) -> Descontinuado (con stock) | G8: 75001339 | H8: =+_xlfn.XLOOKUP(G8,MASTER!B:B,MASTER!A:A) -> 100080257 | I8: =+_xlfn.XLOOKUP(G8,MASTER!B:B,MASTER!C:C) -> MARLBORO CIGARR ROJO 14S CD CAJET | N8: 75052836 | O8: =+_xlfn.XLOOKUP(N8,MASTER!B:B,MASTER!A:A) -> 100005585 | P8: =+_xlfn.XLOOKUP(N8,MASTER!B:B,MASTER!C:C) -> PALL MALL TOKYO MIDNIGHT 20 | Q8: =+_xlfn.XLOOKUP(N8,MASTER!B:B,MASTER!D:D) -> BAT | R8: =+_xlfn.XLOOKUP(N8,MASTER!B:B,MASTER!I:I) -> Activo | S8: =+_xlfn.XLOOKUP(N8,$U$2:$U$16,$V$2:$V$16,"no") -> no | U8: 75064778 | V8: si}
A9: 40331379 | B9: =+_xlfn.XLOOKUP(A9,MASTER!B:B,MASTER!A:A) -> 100080899 | C9: =+_xlfn.XLOOKUP(A9,MASTER!B:B,MASTER!C:C) -> WINSTON CIGARR BLUE 14S CAJET | D9: =+_xlfn.XLOOKUP(A9,MASTER!B:B,MASTER!D:D) -> JTI | E9: =+_xlfn.XLOOKUP(A9,MASTER!B:B,MASTER!I:I) -> Inactivo | G9: 75001360 | H9: =+_xlfn.XLOOKUP(G9,MASTER!B:B,MASTER!A:A) -> 100018656 | I9: =+_xlfn.XLOOKUP(G9,MASTER!B:B,MASTER!C:C) -> MARLBORO VISTA GARDEN 20 1 CAJETILLA | N9: 75063504 | O9: =+_xlfn.XLOOKUP(N9,MASTER!B:B,MASTER!A:A) -> 100012153 | P9: =+_xlfn.XLOOKUP(N9,MASTER!B:B,MASTER!C:C) -> LUCKY STRIKE 20S ME TDC 1PZ | Q9: =+_xlfn.XLOOKUP(N9,MASTER!B:B,MASTER!D:D) -> BAT | R9: =+_xlfn.XLOOKUP(N9,MASTER!B:B,MASTER!I:I) -> Activo | S9: =+_xlfn.XLOOKUP(N9,$U$2:$U$16,$V$2:$V$16,"no") -> no | U9: 75073534 | V9: si}
A10: 42138037 | B10: =+_xlfn.XLOOKUP(A10,MASTER!B:B,MASTER!A:A) -> 100080897 | C10: =+_xlfn.XLOOKUP(A10,MASTER!B:B,MASTER!C:C) -> WINSTON CIGARR CLASSIC 20S CAJET | D10: =+_xlfn.XLOOKUP(A10,MASTER!B:B,MASTER!D:D) -> JTI | E10: =+_xlfn.XLOOKUP(A10,MASTER!B:B,MASTER!I:I) -> Descontinuado (con stock) | G10: 75001384 | H10: =+_xlfn.XLOOKUP(G10,MASTER!B:B,MASTER!A:A) -> 100018872 | I10: =+_xlfn.XLOOKUP(G10,MASTER!B:B,MASTER!C:C) -> MARLBORO VISTA ARTIC 20 1 CAJETILLA | N10: 75064648 | O10: =+_xlfn.XLOOKUP(N10,MASTER!B:B,MASTER!A:A) -> 100012746 | P10: =+_xlfn.XLOOKUP(N10,MASTER!B:B,MASTER!C:C) -> PALL MALL MYKONOS NIGHTFALL 20 | Q10: =+_xlfn.XLOOKUP(N10,MASTER!B:B,MASTER!D:D) -> BAT | R10: =+_xlfn.XLOOKUP(N10,MASTER!B:B,MASTER!I:I) -> Activo | S10: =+_xlfn.XLOOKUP(N10,$U$2:$U$16,$V$2:$V$16,"no") -> no | U10: 75071776 | V10: si}
A11: 42138051 | B11: =+_xlfn.XLOOKUP(A11,MASTER!B:B,MASTER!A:A) -> 100080898 | C11: =+_xlfn.XLOOKUP(A11,MASTER!B:B,MASTER!C:C) -> WINSTON CIGARR BLUE 20S CAJET | D11: =+_xlfn.XLOOKUP(A11,MASTER!B:B,MASTER!D:D) -> JTI | E11: =+_xlfn.XLOOKUP(A11,MASTER!B:B,MASTER!I:I) -> Activo | G11: 75001414 | H11: =+_xlfn.XLOOKUP(G11,MASTER!B:B,MASTER!A:A) -> 100018586 | I11: =+_xlfn.XLOOKUP(G11,MASTER!B:B,MASTER!C:C) -> MARLBORO SELECC ARTESANAL 14 1 CAJETILLA | N11: 75064716 | O11: =+_xlfn.XLOOKUP(N11,MASTER!B:B,MASTER!A:A) -> 100012997 | P11: =+_xlfn.XLOOKUP(N11,MASTER!B:B,MASTER!C:C) -> LUCKY STRIKE ENIGMA 100S 1PZ | Q11: =+_xlfn.XLOOKUP(N11,MASTER!B:B,MASTER!D:D) -> BAT | R11: =+_xlfn.XLOOKUP(N11,MASTER!B:B,MASTER!I:I) -> Activo | S11: =+_xlfn.XLOOKUP(N11,$U$2:$U$16,$V$2:$V$16,"no") -> no | U11: 75074081 | V11: si}
A12: 42230748 | B12: =+_xlfn.XLOOKUP(A12,MASTER!B:B,MASTER!A:A) -> 100017183 | C12: =+_xlfn.XLOOKUP(A12,MASTER!B:B,MASTER!C:C) -> GIZEH PAPEL ZIGZAG 1 PZ | D12: =+_xlfn.XLOOKUP(A12,MASTER!B:B,MASTER!D:D) -> PUROS | E12: =+_xlfn.XLOOKUP(A12,MASTER!B:B,MASTER!I:I) -> Activo | G12: 75001476 | H12: =+_xlfn.XLOOKUP(G12,MASTER!B:B,MASTER!A:A) -> 100080034 | I12: =+_xlfn.XLOOKUP(G12,MASTER!B:B,MASTER!C:C) -> DELICADOS CIGARR OVALADOS CAJET | N12: 75064747 | O12: =+_xlfn.XLOOKUP(N12,MASTER!B:B,MASTER!A:A) -> 100013075 | P12: =+_xlfn.XLOOKUP(N12,MASTER!B:B,MASTER!C:C) -> MONTANA SHOTS 15S 1PZ | Q12: =+_xlfn.XLOOKUP(N12,MASTER!B:B,MASTER!D:D) -> BAT | R12: =+_xlfn.XLOOKUP(N12,MASTER!B:B,MASTER!I:I) -> Activo | S12: =+_xlfn.XLOOKUP(N12,$U$2:$U$16,$V$2:$V$16,"no") -> no | U12: 75079963 | V12: si}
A13: 75001254 | B13: =+_xlfn.XLOOKUP(A13,MASTER!B:B,MASTER!A:A) -> 100080031 | C13: =+_xlfn.XLOOKUP(A13,MASTER!B:B,MASTER!C:C) -> BENSON&HEDGE CIGARR CS CAJET | D13: =+_xlfn.XLOOKUP(A13,MASTER!B:B,MASTER!D:D) -> PMI | E13: =+_xlfn.XLOOKUP(A13,MASTER!B:B,MASTER!I:I) -> Descontinuado (con stock) | G13: 75004385 | H13: =+_xlfn.XLOOKUP(G13,MASTER!B:B,MASTER!A:A) -> 100021977 | I13: =+_xlfn.XLOOKUP(G13,MASTER!B:B,MASTER!C:C) -> FAROS FAROS FAROS 14 1 CAJETILLA | N13: 75064754 | O13: =+_xlfn.XLOOKUP(N13,MASTER!B:B,MASTER!A:A) -> 100013892 | P13: =+_xlfn.XLOOKUP(N13,MASTER!B:B,MASTER!C:C) -> MONTANA SHOTS 1PZ | Q13: =+_xlfn.XLOOKUP(N13,MASTER!B:B,MASTER!D:D) -> BAT | R13: =+_xlfn.XLOOKUP(N13,MASTER!B:B,MASTER!I:I) -> Activo | S13: =+_xlfn.XLOOKUP(N13,$U$2:$U$16,$V$2:$V$16,"no") -> no | U13: 75081058 | V13: si}
... A16: 75001339 | B16: =+_xlfn.XLOOKUP(A16,MASTER!B:B,MASTER!A:A) -> 100080257 | C16: =+_xlfn.XLOOKUP(A16,MASTER!B:B,MASTER!C:C) -> MARLBORO CIGARR ROJO 14S CD CAJET | D16: =+_xlfn.XLOOKUP(A16,MASTER!B:B,MASTER!D:D) -> PMI | E16: =+_xlfn.XLOOKUP(A16,MASTER!B:B,MASTER!I:I) -> Activo | G16: 75004415 | H16: =+_xlfn.XLOOKUP(G16,MASTER!B:B,MASTER!A:A) -> 100022276 | I16: =+_xlfn.XLOOKUP(G16,MASTER!B:B,MASTER!C:C) -> MARLBORO EXOTIC VISTA EXOTIC 1 CAJETILLA | N16: 75071479 | O16: =+_xlfn.XLOOKUP(N16,MASTER!B:B,MASTER!A:A) -> 100016412 | P16: =+_xlfn.XLOOKUP(N16,MASTER!B:B,MASTER!C:C) -> PALL MALL WHITE 20 | Q16: =+_xlfn.XLOOKUP(N16,MASTER!B:B,MASTER!D:D) -> BAT | R16: =+_xlfn.XLOOKUP(N16,MASTER!B:B,MASTER!I:I) -> Activo | S16: =+_xlfn.XLOOKUP(N16,$U$2:$U$16,$V$2:$V$16,"no") -> no | U16: 75084141 | V16: si}
A17: 75001360 | B17: =+_xlfn.XLOOKUP(A17,MASTER!B:B,MASTER!A:A) -> 100018656 | C17: =+_xlfn.XLOOKUP(A17,MASTER!B:B,MASTER!C:C) -> MARLBORO VISTA GARDEN 20 1 CAJETILLA | D17: =+_xlfn.XLOOKUP(A17,MASTER!B:B,MASTER!D:D) -> PMI | E17: =+_xlfn.XLOOKUP(A17,MASTER!B:B,MASTER!I:I) -> Activo | G17: 75005481 | H17: =+_xlfn.XLOOKUP(G17,MASTER!B:B,MASTER!A:A) -> 100021048 | I17: =+_xlfn.XLOOKUP(G17,MASTER!B:B,MASTER!C:C) -> LM LM 25S 25S 1 CAJETILLA | N17: 75071776 | O17: =+_xlfn.XLOOKUP(N17,MASTER!B:B,MASTER!A:A) -> 100017982 | P17: =+_xlfn.XLOOKUP(N17,MASTER!B:B,MASTER!C:C) -> PALL MALL CLASSICS 20 | Q17: =+_xlfn.XLOOKUP(N17,MASTER!B:B,MASTER!D:D) -> BAT | R17: =+_xlfn.XLOOKUP(N17,MASTER!B:B,MASTER!I:I) -> Activo | S17: =+_xlfn.XLOOKUP(N17,$U$2:$U$16,$V$2:$V$16,"no") -> si}
A18: 75001384 | B18: =+_xlfn.XLOOKUP(A18,MASTER!B:B,MASTER!A:A) -> 100018872 | C18: =+_xlfn.XLOOKUP(A18,MASTER!B:B,MASTER!C:C) -> MARLBORO VISTA ARTIC 20 1 CAJETILLA | D18: =+_xlfn.XLOOKUP(A18,MASTER!B:B,MASTER!D:D) -> PMI | E18: =+_xlfn.XLOOKUP(A18,MASTER!B:B,MASTER!I:I) -> Activo | G18: 75006204 | H18: =+_xlfn.XLOOKUP(G18,MASTER!B:B,MASTER!A:A) -> 101000061 | I18: =+_xlfn.XLOOKUP(G18,MASTER!B:B,MASTER!C:C) -> MARLBORO CARIBBEAN FUSION 100 BOX 14 CAJETILLA PZ | N18: 75073534 | O18: =+_xlfn.XLOOKUP(N18,MASTER!B:B,MASTER!A:A) -> 100018746 | P18: =+_xlfn.XLOOKUP(N18,MASTER!B:B,MASTER!C:C) -> PALL MALL EX RED 15 1 CAJETILLA | Q18: =+_xlfn.XLOOKUP(N18,MASTER!B:B,MASTER!D:D) -> BAT | R18: =+_xlfn.XLOOKUP(N18,MASTER!B:B,MASTER!I:I) -> Descontinuado (con stock) | S18: =+_xlfn.XLOOKUP(N18,$U$2:$U$16,$V$2:$V$16,"no") -> si}
